Workbook
Name מקרא: מקרא!$B$5:$B$34
Name סימון: [1]מקרא!$B$3:$B$31

Sheet ינואר
A1: ינואר טבת-שבט | AT1: 1 | AW1: עובדי משמרת | CC1: 1
D2: מדור פיקוד ובקרה | X2: רמ"ד פיקוד | Z2: רמ"ח | AB2: ה.חשמל\מ. מחסן | AF2: רמ"ד ת.מסלול | AH2: מדור תאורת מסלולים | AP2: הערות | AR2: רכבים | AW2: משמרת 1 | BE2: משמרת 2 | BM2: משמרת 3 | BU2: משמרת 4 | CF2: כמות עובדים | CH2: עבודות מסלולים | CJ2: הערות
D3: קובי דניאלי | F3: תומר סער | H3: עמית נדל | J3: דניאל סויסה | L3: מיכאל דניאל | N3: יואב ברדוגו | P3: דוד מהלו | R3: אלון איברנדי | T3: סהר קובה | V3: שגיב בניתה | X3: אבי מנור | Z3: אהרון שוחמי | AB3: איציק אפרמשוילי | AD3: אבי שמואלי | AF3: שמוליק פוגל | AH3: אלי פבלוב | AJ3: ראובן בוזנח | AL3: גיטאו אבבה | AN3: תומר ליבוביץ | AW3: שתה בירו | AY3: ליאור אברהם | BA3: ברק מור | BC3: אדם כהן | BE3: מרבי קריכלי | BG3: ירון טייב | BI3: עמרי סלמן | BK3: גבריאל וכטרמן | BM3: שלומי חן | BO3: אור שלו | BQ3: עומר גבע | BS3: איציק חוחא | BU3: מוטי חלפון | BW3: שי סואד | BY3: דור שרוני | CA3: אורגד שניאור
D4: =HYPERLINK("maiLto:" & מיילים!B9 & "?subject=" & מיילים!G$3 & "&body=" & מיילים!H$3,"עדכון במייל") -> עדכון במייל | F4: =HYPERLINK("maiLto:" & מיילים!B10 & "?subject=" & מיילים!G$3 & "&body=" & מיילים!H$3,"עדכון במייל") -> עדכון במייל | H4: =HYPERLINK("maiLto:" & מיילים!B11 & "?subject=" & מיילים!G$3 & "&body=" & מיילים!H$3,"עדכון במייל") -> עדכון במייל | J4: =HYPERLINK("maiLto:" & מיילים!B12 & "?subject=" & מיילים!G$3 & "&body=" & מיילים!H$3,"עדכון במייל") -> עדכון במייל | L4: =HYPERLINK("maiLto:" & מיילים!B13 & "?subject=" & מיילים!G$3 & "&body=" & מיילים!H$3,"עדכון במייל") -> עדכון במייל | N4: =HYPERLINK("maiLto:" & מיילים!B6 & "?subject=" & מיילים!G$3 & "&body=" & מיילים!H$3,"עדכון במייל") -> עדכון במייל | P4: =HYPERLINK("maiLto:" & מיילים!B14 & "?subject=" & מיילים!G$3 & "&body=" & מיילים!H$3,"עדכון במייל") -> עדכון במייל | R4: =HYPERLINK("maiLto:" & מיילים!B34 & "?subject=" & מיילים!G$3 & "&body=" & מיילים!H$3,"עדכון במייל") -> עדכון במייל | T4: =HYPERLINK("maiLto:" & מיילים!B36 & "?subject=" & מיילים!G$3 & "&body=" & מיילים!H$3,"עדכון במייל") -> עדכון במייל | V4: =HYPERLINK("maiLto:" & מיילים!B35 & "?subject=" & מיילים!G$3 & "&body=" & מיילים!H$3,"עדכון במייל") -> עדכון במייל | X4: =HYPERLINK("maiLto:" & מיילים!B16 & "?subject=" & מיילים!G$3 & "&body=" & מיילים!H$3,"עדכון במייל") -> עדכון במייל | Z4: =HYPERLINK("maiLto:" & מיילים!B4 & "?subject=" & מיילים!G$3 & "&body=" & מיילים!H$3,"עדכון במייל") -> עדכון במייל | AB4: =HYPERLINK("maiLto:" & מיילים!B7 & "?subject=" & מיילים!G$3 & "&body=" & מיילים!H$3,"עדכון במייל") -> עדכון במייל | AD4: =HYPERLINK("maiLto:" & מיילים!B8 & "?subject=" & מיילים!G$3 & "&body=" & מיילים!H$3,"עדכון במייל") -> עדכון במייל | AF4: =HYPERLINK("maiLto:" & מיילים!B5 & "?subject=" & מיילים!G$3 & "&body=" & מיילים!H$3,"עדכון במייל") -> עדכון במייל | AH4: =HYPERLINK("maiLto:" & מיילים!B15 & "?subject=" & מיילים!G$3 & "&body=" & מיילים!H$3,"עדכון במייל") -> עדכון במייל | AJ4: =HYPERLINK("maiLto:" & מיילים!B17 & "?subject=" & מיילים!G$3 & "&body=" & מיילים!H$3,"עדכון במייל") -> עדכון במייל | AL4: =HYPERLINK("maiLto:" & מיילים!B37 & "?subject=" & מיילים!G$3 & "&body=" & מיילים!H$3,"עדכון במייל") -> עדכון במייל | AN4: =HYPERLINK("maiLto:" & מיילים!B38 & "?subject=" & מיילים!G$3 & "&body=" & מיילים!H$3,"עדכון במייל") -> עדכון במייל | AR4: DMAX | AS4: Staria | AW4: =HYPERLINK("maiLto:" & מיילים!B18 & "?subject=" & מיילים!G$3 & "&body=" & מיילים!H$3,"עדכון במייל") -> עדכון במייל | AY4: =HYPERLINK("maiLto:" & מיילים!B20 & "?subject=" & מיילים!G$3 & "&body=" & מיילים!H$3,"עדכון במייל") -> עדכון במייל | BA4: =HYPERLINK("maiLto:" & מיילים!B31 & "?subject=" & מיילים!G$3 & "&body=" & מיילים!H$3,"עדכון במייל") -> עדכון במייל | BC4: =HYPERLINK("maiLto:" & מיילים!B32 & "?subject=" & מיילים!G$3 & "&body=" & מיילים!H$3,"עדכון במייל") -> עדכון במייל | BE4: =HYPERLINK("maiLto:" & מיילים!B22 & "?subject=" & מיילים!G$3 & "&body=" & מיילים!H$3,"עדכון במייל") -> עדכון במייל | BG4: =HYPERLINK("maiLto:" & מיילים!B23 & "?subject=" & מיילים!G$3 & "&body=" & מיילים!H$3,"עדכון במייל") -> עדכון במייל | BI4: =HYPERLINK("maiLto:" & מיילים!B24 & "?subject=" & מיילים!G$3 & "&body=" & מיילים!H$3,"עדכון במייל") -> עדכון במייל | BK4: =HYPERLINK("maiLto:" & מיילים!B25 & "?subject=" & מיילים!G$3 & "&body=" & מיילים!H$3,"עדכון במייל") -> עדכון במייל | BM4: =HYPERLINK("maiLto:" & מיילים!B26 & "?subject=" & מיילים!G$3 & "&body=" & מיילים!H$3,"עדכון במייל") -> עדכון במייל | BO4: =HYPERLINK("maiLto:" & מיילים!R19 & "?subject=" & מיילים!W$3 & "&body=" & מיילים!X$3,"עדכון במייל") -> עדכון במייל | BQ4: =HYPERLINK("maiLto:" & מיילים!P21 & "?subject=" & מיילים!U$3 & "&body=" & מיילים!V$3,"עדכון במייל") -> עדכון במייל | BS4: =HYPERLINK("maiLto:" & מיילים!B27 & "?subject=" & מיילים!G$3 & "&body=" & מיילים!H$3,"עדכון במייל") -> עדכון במייל | BU4: =HYPERLINK("maiLto:" & מיילים!B28 & "?subject=" & מיילים!G$3 & "&body=" & מיילים!H$3,"עדכון במייל") -> עדכון במייל | BW4: =HYPERLINK("maiLto:" & מיילים!B29 & "?subject=" & מיילים!G$3 & "&body=" & מיילים!H$3,"עדכון במייל") -> עדכון במייל | BY4: =HYPERLINK("maiLto:" & מיילים!B30 & "?subject=" & מיילים!G$3 & "&body=" & מיילים!H$3,"עדכון במייל") -> עדכון במייל | CA4: =HYPERLINK("maiLto:" & מיילים!P33 & "?subject=" & מיילים!U$3 & "&body=" & מיילים!V$3,"עדכון במייל") -> עדכון במייל | CF4: יום | CG4: לילה | CH4: עבודות יום | CI4: עבודות לילה
A5: 1 | B5: יום ה | C5: 1 | D5: ח | K5: כ | V5: מיל | AD5: מ | AJ5: מ | AM5: כמ | AT5: 1 | AU5: יום ה | AV5: 1 | BF5: ח | BH5: ל | BJ5: ל | BL5: ל | BN5: י | BP5: י | BR5: מיל | BT5: פ | CC5: 1 | CD5: יום ה | CE5: 1 | CF5: =COUNTIF(AX5:CB5,"י")+COUNTIF(AX5:CB5,"Y")+COUNTIF(AX5:CB5,"2") -> 2 | CG5: =COUNTIF(AW5:CB5,"ל")+COUNTIF(AW5:CB5,"L")+COUNTIF(AW5:CB5,"ל2") -> 3
A6: 2 | B6: יום ו | O6: כש | X6: ח | AD6: מ | AG6: כמש | AT6: 2 | AU6: יום ו | BN6: ל | BP6: ל | BR6: פ | BT6: ל | BV6: י | BX6: פ | BZ6: י | CB6: י | CC6: 2 | CD6: יום ו | CF6: =COUNTIF(AX6:CB6,"י")+COUNTIF(AX6:CB6,"Y")+COUNTIF(AX6:CB6,"2") -> 3 | CG6: =COUNTIF(AW6:CB6,"ל")+COUNTIF(AW6:CB6,"L")+COUNTIF(AW6:CB6,"ל2") -> 3
A7: 3 | B7: שבת | O7: כש | X7: ח | AD7: מ | AG7: כמש | AT7: 3 | AU7: שבת | AX7: י | AZ7: י | BB7: י | BD7: י | BR7: פ | BV7: ל | BX7: ל | BZ7: ל | CB7: ל | CC7: 3 | CD7: שבת | CF7: =COUNTIF(AX7:CB7,"י")+COUNTIF(AX7:CB7,"Y")+COUNTIF(AX7:CB7,"2") -> 4 | CG7: =COUNTIF(AW7:CB7,"ל")+COUNTIF(AW7:CB7,"L")+COUNTIF(AW7:CB7,"ל2") -> 4 | CH7: מסלול
A8: 4 | B8: יום א | C8: 2 | L8: ראש פינה | R8: ראש פינה | X8: ח | AC8: כ | AD8: מ | AH8: ראש פינה | AK8: כמ | AN8: ראש פינה | AT8: 4 | AU8: יום א | AX8: ל | AZ8: ל | BB8: ל | BD8: ל | BF8: מ | BH8: י | BJ8: י | BL8: י | BR8: מיל | BX8: L | CC8: 4 | CD8: יום א | CF8: =COUNTIF(AX8:CB8,"י")+COUNTIF(AX8:CB8,"Y")+COUNTIF(AX8:CB8,"2") -> 3 | CG8: =COUNTIF(AW8:CB8,"ל")+COUNTIF(AW8:CB8,"L")+COUNTIF(AW8:CB8,"ל2") -> 5 | CI8: מסלול
A9: 5 | B9: יום ב | K9: כ | X9: ח | AB9: ח | AD9: מ | AH9: ק | AL9: ק | AO9: כמ | AT9: 5 | AU9: יום ב | AV9: 2 | BF9: מ | BH9: ל | BJ9: ל | BL9: ל | BN9: י | BP9: י | BR9: מיל | BT9: פ | CC9: 5 | CD9: יום ב | CE9: 2 | CF9: =COUNTIF(AX9:CB9,"י")+COUNTIF(AX9:CB9,"Y")+COUNTIF(AX9:CB9,"2") -> 2 | CG9: =COUNTIF(AW9:CB9,"ל")+COUNTIF(AW9:CB9,"L")+COUNTIF(AW9:CB9,"ל2") -> 3 | CI9: מסלול
A10: 6 | B10: יום ג | D10: חיפה | F10: חיפה | J10: חיפה | N10: PBB | R10: PBB | X10: ח | AC10: כ | AD10: מ | AJ10: חיפה | AO10: כמ | AT10: 6 | AU10: יום ג | BJ10: L | BN10: ל | BP10: ל | BR10: מיל | BT10: ל | BV10: י | BX10: י | BZ10: י | CB10: י | CC10: 6 | CD10: יום ג | CF10: =COUNTIF(AX10:CB10,"י")+COUNTIF(AX10:CB10,"Y")+COUNTIF(AX10:CB10,"2") -> 4 | CG10: =COUNTIF(AW10:CB10,"ל")+COUNTIF(AW10:CB10,"L")+COUNTIF(AW10:CB10,"ל2") -> 4
A11: 7 | B11: יום ד | R11: ניקיון תחנות | X11: ח | AD11: מ | AJ11: ח | AM11: כמ | AN11: גיבוש | AO11: כ | AT11: 7 | AU11: יום ד | AX11: י | AZ11: ח | BB11: י | BD11: י | BN11: ק | BR11: מיל | BV11: ל | BX11: ל | BZ11: ל | CB11: ל | CC11: 7 | CD11: יום ד | CF11: =COUNTIF(AX11:CB11,"י")+COUNTIF(AX11:CB11,"Y")+COUNTIF(AX11:CB11,"2") -> 3 | CG11: =COUNTIF(AW11:CB11,"ל")+COUNTIF(AW11:CB11,"L")+COUNTIF(AW11:CB11,"ל2") -> 4
A12: 8 | B12: יום ה | D12: ח | K12: כ | X12: ח | AD12: מ | AH12: ק | AM12: כמ | AN12: ח | AT12: 8 | AU12: יום ה | AX12: ל | AZ12: ל | BB12: ל | BD12: ל | BF12: י | BH12: י | BJ12: פ | BL12: ח | BR12: מיל | CC12: 8 | CD12: יום ה | CF12: =COUNTIF(AX12:CB12,"י")+COUNTIF(AX12:CB12,"Y")+COUNTIF(AX12:CB12,"2") -> 2 | CG12: =COUNTIF(AW12:CB12,"ל")+COUNTIF(AW12:CB12,"L")+COUNTIF(AW12:CB12,"ל2") -> 4
A13: 9 | B13: יום ו | M13: כש | V13: ח | AI13: כמש | AT13: 9 | AU13: יום ו | BF13: ל | BH13: ל | BJ13: ל | BL13: ל | BN13: י | BP13: י | BR13: פ | BT13: י | CC13: 9 | CD13: יום ו | CF13: =COUNTIF(AX13:CB13,"י")+COUNTIF(AX13:CB13,"Y")+COUNTIF(AX13:CB13,"2") -> 3 | CG13: =COUNTIF(AW13:CB13,"ל")+COUNTIF(AW13:CB13,"L")+COUNTIF(AW13:CB13,"ל2") -> 4
A14: 10 | B14: שבת | G14: כש | V14: ח | AG14: כמש | AT14: 10 | AU14: שבת | BN14: ל | BP14: ל | BR14: פ | BT14: ל | BV14: פ | BX14: י | BZ14: י | CB14: י | CC14: 10 | CD14: שבת | CF14: =COUNTIF(AX14:CB14,"י")+COUNTIF(AX14:CB14,"Y")+COUNTIF(AX14:CB14,"2") -> 3 | CG14: =COUNTIF(AW14:CB14,"ל")+COUNTIF(AW14:CB14,"L")+COUNTIF(AW14:CB14,"ל2") -> 3
A15: 11 | B15: יום א | C15: 3 | H15: מ | P15: מ | V15: ח | AC15: כ | AE15: כמ | AT15: 11 | AU15: יום א | AX15: י | AZ15: ח | BB15: י | BD15: י | BF15: ח | BR15: מיל | BV15: ל | BX15: ל | BZ15: ל | CB15: ל | CC15: 11 | CD15: יום א | CF15: =COUNTIF(AX15:CB15,"י")+COUNTIF(AX15:CB15,"Y")+COUNTIF(AX15:CB15,"2") -> 3 | CG15: =COUNTIF(AW15:CB15,"ל")+COUNTIF(AW15:CB15,"L")+COUNTIF(AW15:CB15,"ל2") -> 4 | CI15: מסלול
A16: 12 | B16: יום ב | F16: ק | H16: ק | M16: כמ | P16: מ | R16: מ | V16: ח | AA16: פ | AC16: כ | AH16: ק | AL16: ק | AT16: 12 | AU16: יום ב | AV16: 3 | AX16: ל | AZ16: ל | BB16: ל | BD16: ל | BF16: ח | BH16: י | BJ16: י | BL16: י | BR16: מיל | CC16: 12 | CD16: יום ב | CE16: 3 | CF16: =COUNTIF(AX16:CB16,"י")+COUNTIF(AX16:CB16,"Y")+COUNTIF(AX16:CB16,"2") -> 3 | CG16: =COUNTIF(AW16:CB16,"ל")+COUNTIF(AW16:CB16,"L")+COUNTIF(AW16:CB16,"ל2") -> 4
A17: 13 | B17: יום ג | D17: מ | L17: מ | N17: רמון | P17: מ | R17: מ | U17: כ | V17: ח | Z17: ח | AC17: כמ | AT17: 13 | AU17: יום ג | BF17: ח | BH17: ל | BJ17: ל | BL17: ל | BN17: י | BP17: י | BR17: מיל | BT17: י | CB17: Y | CC17: 13 | CD17: יום ג | CF17: =COUNTIF(AX17:CB17,"י")+COUNTIF(AX17:CB17,"Y")+COUNTIF(AX17:CB17,"2") -> 4 | CG17: =COUNTIF(AW17:CB17,"ל")+COUNTIF(AW17:CB17,"L")+COUNTIF(AW17:CB17,"ל2") -> 3 | CI17: מסלול
A18: 14 | B18: יום ד | E18: כ | J18: מיל | N18: רמון | Q18: כמ | R18: מ | V18: ח | Z18: ח | AB18: ח | AJ18: מ | AP18: בטיחות כללית | AT18: 14 | AU18: יום ד | BD18: 2 | BF18: ח | BN18: ל | BP18: ל | BR18: מיל | BT18: ל | BV18: י | BX18: י | BZ18: י | CB18: י | CC18: 14 | CD18: יום ד | CF18: =COUNTIF(AX18:CB18,"י")+COUNTIF(AX18:CB18,"Y")+COUNTIF(AX18:CB18,"2") -> 5 | CG18: =COUNTIF(AW18:CB18,"ל")+COUNTIF(AW18:CB18,"L")+COUNTIF(AW18:CB18,"ל2") -> 3 | CJ18: בטיחות כללית
A19: 15 | B19: יום ה | J19: מיל | N19: רמון | Q19: כמ | S19: כ | V19: ח | Z19: ח | AD19: מ | AN19: ח | AP19: חג ערבי | AT19: 15 | AU19: יום ה | AX19: י | AZ19: י | BB19: י | BD19: י | BF19: ח | BR19: מיל | BT19: L | BV19: ל | BX19: ל | BZ19: ל | CB19: ל | CC19: 15 | CD19: יום ה | CF19: =COUNTIF(AX19:CB19,"י")+COUNTIF(AX19:CB19,"Y")+COUNTIF(AX19:CB19,"2") -> 4 | CG19: =COUNTIF(AW19:CB19,"ל")+COUNTIF(AW19:CB19,"L")+COUNTIF(AW19:CB19,"ל2") -> 5
A20: 16 | B20: יום ו | J20: מיל | V20: ח | Y20: כש | AD20: מ | AI20: כמש | AP20: חג ערבי | AT20: 16 | AU20: יום ו | AX20: ל | AZ20: ל | BB20: ל | BD20: ל | BF20: פ | BH20: י | BJ20: י | BL20: י | BR20: פ | CC20: 16 | CD20: יום ו | CF20: =COUNTIF(AX20:CB20,"י")+COUNTIF(AX20:CB20,"Y")+COUNTIF(AX20:CB20,"2") -> 3 | CG20: =COUNTIF(AW20:CB20,"ל")+COUNTIF(AW20:CB20,"L")+COUNTIF(AW20:CB20,"ל2") -> 4
A21: 17 | B21: שבת | J21: מיל | V21: ח | Y21: כש | AD21: מ | AI21: כמש | AT21: 17 | AU21: שבת | BF21: פ | BH21: ל | BJ21: ל | BL21: ל | BN21: י | BP21: י | BR21: פ | BT21: פ | CC21: 17 | CD21: שבת | CF21: =COUNTIF(AX21:CB21,"י")+COUNTIF(AX21:CB21,"Y")+COUNTIF(AX21:CB21,"2") -> 2 | CG21: =COUNTIF(AW21:CB21,"ל")+COUNTIF(AW21:CB21,"L")+COUNTIF(AW21:CB21,"ל2") -> 3
A22: 18 | B22: יום א | C22: 4 | E22: כ | J22: מיל | V22: מיל | X22: מ | AD22: מ | AK22: כמ | AL22: ק | AT22: 18 | AU22: יום א | BN22: ל | BP22: ל | BR22: מיל | BT22: ל | BV22: י | BX22: י | BZ22: י | CB22: י | CC22: 18 | CD22: יום א | CF22: =COUNTIF(AX22:CB22,"י")+COUNTIF(AX22:CB22,"Y")+COUNTIF(AX22:CB22,"2") -> 4 | CG22: =COUNTIF(AW22:CB22,"ל")+COUNTIF(AW22:CB22,"L")+COUNTIF(AW22:CB22,"ל2") -> 3
A23: 19 | B23: יום ב | D23: יום וולנס | F23: ק | H23: ק | J23: מיל | N23: ה.ב | S23: כ | T23: ה.ב | V23: מיל | X23: ה.ב | AH23: ק | AK23: כמ | AN23: יום וולנס | AT23: 19 | AU23: יום ב | AV23: 4 | AX23: י | AZ23: י | BB23: י | BD23: י | BR23: מיל | BT23: L | BV23: ל | BX23: ל | BZ23: ל | CB23: ל | CC23: 19 | CD23: יום ב | CE23: 4 | CF23: =COUNTIF(AX23:CB23,"י")+COUNTIF(AX23:CB23,"Y")+COUNTIF(AX23:CB23,"2") -> 4 | CG23: =COUNTIF(AW23:CB23,"ל")+COUNTIF(AW23:CB23,"L")+COUNTIF(AW23:CB23,"ל2") -> 5
A24: 20 | B24: יום ג | D24: מ | H24: ח | J24: ח | M24: כ | Q24: כמ | V24: מיל | X24: ב. חשמל | AD24: ב. חשמל | AF24: ב. חשמל | AJ24: מ | AL24: ב. חשמל | AN24: ב. חשמל | AT24: 20 | AU24: יום ג | AX24: ל | AZ24: ל | BB24: ל | BD24: ל | BF24: מ | BH24: י | BJ24: י | BL24: י | BR24: מיל | CC24: 20 | CD24: יום ג | CF24: =COUNTIF(AX24:CB24,"י")+COUNTIF(AX24:CB24,"Y")+COUNTIF(AX24:CB24,"2") -> 3 | CG24: =COUNTIF(AW24:CB24,"ל")+COUNTIF(AW24:CB24,"L")+COUNTIF(AW24:CB24,"ל2") -> 4
A25: 21 | B25: יום ד | D25: מ | I25: כמ | J25: ח | R25: הרצליה | U25: כ | V25: מיל | AJ25: מ | AT25: 21 | AU25: יום ד | BD25: L | BF25: מ | BH25: ל | BJ25: ל | BL25: ח | BN25: י | BP25: י | BR25: מיל | BT25: L | BX25: Y | CB25: Y | CC25: 21 | CD25: יום ד | CF25: =COUNTIF(AX25:CB25,"י")+COUNTIF(AX25:CB25,"Y")+COUNTIF(AX25:CB25,"2") -> 4 | CG25: =COUNTIF(AW25:CB25,"ל")+COUNTIF(AW25:CB25,"L")+COUNTIF(AW25:CB25,"ל2") -> 4
A26: 22 | B26: יום ה | D26: מ | G26: כמ | J26: ח | R26: מ | U26: כ | V26: מיל | X26: ראש פינה | AT26: 22 | AU26: יום ה | BL26: ח | BN26: ל | BP26: ל | BR26: מיל | BT26: ל | BV26: י | BX26: פ | BZ26: י | CB26: י | CC26: 22 | CD26: יום ה | CF26: =COUNTIF(AX26:CB26,"י")+COUNTIF(AX26:CB26,"Y")+COUNTIF(AX26:CB26,"2") -> 3 | CG26: =COUNTIF(AW26:CB26,"ל")+COUNTIF(AW26:CB26,"L")+COUNTIF(AW26:CB26,"ל2") -> 3
A27: 23 | B27: יום ו | J27: ח | Y27: כש | AG27: כמש | AH27: שישי | AL27: שישי | AP27: עבודות שישי | AT27: 23 | AU27: יום ו | AX27: י | AZ27: פ | BB27: י | BD27: י | BL27: ח | BN27: L | BR27: פ | BV27: פ | BX27: ל | BZ27: ל | CB27: ל | CC27: 23 | CD27: יום ו | CF27: =COUNTIF(AX27:CB27,"י")+COUNTIF(AX27:CB27,"Y")+COUNTIF(AX27:CB27,"2") -> 3 | CG27: =COUNTIF(AW27:CB27,"ל")+COUNTIF(AW27:CB27,"L")+COUNTIF(AW27:CB27,"ל2") -> 4
A28: 24 | B28: שבת | J28: ח | O28: כש | AE28: כמש | AT28: 24 | AU28: שבת | AX28: ל | AZ28: ל | BB28: ל | BD28: ל | BF28: י | BH28: פ | BJ28: י | BL28: ח | BR28: פ | CC28: 24 | CD28: שבת | CF28: =COUNTIF(AX28:CB28,"י")+COUNTIF(AX28:CB28,"Y")+COUNTIF(AX28:CB28,"2") -> 2 | CG28: =COUNTIF(AW28:CB28,"ל")+COUNTIF(AW28:CB28,"L")+COUNTIF(AW28:CB28,"ל2") -> 4
A29: 25 | B29: יום א | C29: 5 | F29: ראש פינה | J29: ח | L29: ב. כללית | N29: ב. כללית | R29: ב. כללית | T29: ראש פינה | V29: ב. כללית | W29: כ | X29: חיפה | AB29: ראש פינה | AD29: ח | AH29: חיפה | AJ29: ראש פינה | AL29: ק | AM29: כמ | AP29: בטיחות כללית | AT29: 25 | AU29: יום א | BD29: L | BF29: ל | BH29: ל | BJ29: ל | BL29: ח | BN29: ח | BP29: י | BR29: מיל | BT29: י | CC29: 25 | CD29: יום א | CF29: =COUNTIF(AX29:CB29,"י")+COUNTIF(AX29:CB29,"Y")+COUNTIF(AX29:CB29,"2") -> 2 | CG29: =COUNTIF(AW29:CB29,"ל")+COUNTIF(AW29:CB29,"L")+COUNTIF(AW29:CB29,"ל2") -> 4 | CI29: מסלול | CJ29: בטיחות כללית
A30: 26 | B30: יום ב | D30: מ | F30: ק | H30: ק | J30: ח | O30: כמ | T30: מ | W30: כ | AH30: ק | AT30: 26 | AU30: יום ב | AV30: 5 | BL30: ח | BN30: ח | BP30: ל | BR30: מיל | BT30: ל | BV30: י | BX30: ק | BZ30: י | CB30: י | CC30: 26 | CD30: יום ב | CE30: 5 | CF30: =COUNTIF(AX30:CB30,"י")+COUNTIF(AX30:CB30,"Y")+COUNTIF(AX30:CB30,"2") -> 3 | CG30: =COUNTIF(AW30:CB30,"ל")+COUNTIF(AW30:CB30,"L")+COUNTIF(AW30:CB30,"ל2") -> 2
A31: 27 | B31: יום ג | G31: כמ | J31: ח | N31: ב. חשמל | R31: ב. חשמל | S31: כ | T31: ב. חשמל | V31: ב. חשמל | AH31: ב. חשמל | AJ31: ב. חשמל | AP31: בטיחות חשמל | AT31: 27 | AU31: יום ג | AX31: י | AZ31: י | BB31: י | BD31: י | BL31: ח | BN31: ח | BT31: ל | BV31: ל | BX31: ל | BZ31: ל | CB31: ל | CC31: 27 | CD31: יום ג | CF31: =COUNTIF(AX31:CB31,"י")+COUNTIF(AX31:CB31,"Y")+COUNTIF(AX31:CB31,"2") -> 4 | CG31: =COUNTIF(AW31:CB31,"ל")+COUNTIF(AW31:CB31,"L")+COUNTIF(AW31:CB31,"ל2") -> 5
A32: 28 | B32: יום ד | I32: כמ | J32: ח | W32: כ | AP32: אסיפת מחלקה 09:00 | AT32: 28 | AU32: יום ד | AX32: ח | AZ32: ל | BB32: ל | BD32: ל | BF32: י | BH32: י | BJ32: י | BL32: ח | BN32: Y | BX32: L | CC32: 28 | CD32: יום ד | CF32: =COUNTIF(AX32:CB32,"י")+COUNTIF(AX32:CB32,"Y")+COUNTIF(AX32:CB32,"2") -> 4 | CG32: =COUNTIF(AW32:CB32,"ל")+COUNTIF(AW32:CB32,"L")+COUNTIF(AW32:CB32,"ל2") -> 4
A33: 29 | B33: יום ה | E33: כ | I33: כמ | J33: ח | N33: ה.ב | V33: ה.ב | AJ33: ח | AT33: 29 | AU33: יום ה | AZ33: L | BF33: ל | BH33: ל | BJ33: ל | BL33: ח | BN33: ח | BP33: י | BR33: פ | BT33: ח | CC33: 29 | CD33: יום ה | CF33: =COUNTIF(AX33:CB33,"י")+COUNTIF(AX33:CB33,"Y")+COUNTIF(AX33:CB33,"2") -> 1 | CG33: =COUNTIF(AW33:CB33,"ל")+COUNTIF(AW33:CB33,"L")+COUNTIF(AW33:CB33,"ל2") -> 4
A34: 30 | B34: יום ו | J34: מיל | Y34: כש | AE34: כמש | AT34: 30 | AU34: יום ו | BL34: ח | BN34: ל | BP34: ל | BR34: ל | BT34: פ | BV34: י | BX34: פ | BZ34: י | CB34: י | CC34: 30 | CD34: יום ו | CF34: =COUNTIF(AX34:CB34,"י")+COUNTIF(AX34:CB34,"Y")+COUNTIF(AX34:CB34,"2") -> 3 | CG34: =COUNTIF(AW34:CB34,"ל")+COUNTIF(AW34:CB34,"L")+COUNTIF(AW34:CB34,"ל2") -> 3
A35: 31 | B35: שבת | J35: מיל | Y35: כש | AE35: כמש | AT35: 31 | AU35: שבת | AX35: י | AZ35: י | BB35: י | BD35: ל | BL35: ח | BN35: L | BV35: ל | BX35: פ | BZ35: ל | CB35: י | CC35: 31 | CD35: שבת | CF35: =COUNTIF(AX35:CB35,"י")+COUNTIF(AX35:CB35,"Y")+COUNTIF(AX35:CB35,"2") -> 4 | CG35: =COUNTIF(AW35:CB35,"ל")+COUNTIF(AW35:CB35,"L")+COUNTIF(AW35:CB35,"ל2") -> 4
D36: =(COUNTIF(D1:D35,"הרצליה")+COUNTIF(D1:D35,"חיפה")+COUNTIF(D1:D35,"רמון")+COUNTIF(D1:D35,"ראש פינה")+COUNTIF(D1:D35,"ה.ב")) -> 1 | E36: =(COUNTIF(E1:E35,"כ")+COUNTIF(E1:E35,"כמ"))*6+(COUNTIF(E1:E35,"כש")+COUNTIF(E1:E35,"כמש"))*10 -> 18 | F36: =(COUNTIF(F1:F35,"הרצליה")+COUNTIF(F1:F35,"חיפה")+COUNTIF(F1:F35,"רמון")+COUNTIF(F1:F35,"ראש פינה")+COUNTIF(F1:F35,"ה.ב")) -> 2 | G36: =(COUNTIF(G1:G35,"כ")+COUNTIF(G1:G35,"כמ"))*6+(COUNTIF(G1:G35,"כש")+COUNTIF(G1:G35,"כמש"))*10 -> 22 | H36: =(COUNTIF(H1:H35,"הרצליה")+COUNTIF(H1:H35,"חיפה")+COUNTIF(H1:H35,"רמון")+COUNTIF(H1:H35,"ראש פינה")+COUNTIF(H1:H35,"ה.ב")) -> 0 | I36: =(COUNTIF(I1:I35,"כ")+COUNTIF(I1:I35,"כמ"))*6+(COUNTIF(I1:I35,"כש")+COUNTIF(I1:I35,"כמש"))*10 -> 18 | J36: =(COUNTIF(J1:J35,"הרצליה")+COUNTIF(J1:J35,"חיפה")+COUNTIF(J1:J35,"רמון")+COUNTIF(J1:J35,"ראש פינה")+COUNTIF(J1:J35,"ה.ב")) -> 1 | K36: =(COUNTIF(K1:K35,"כ")+COUNTIF(K1:K35,"כמ"))*6+(COUNTIF(K1:K35,"כש")+COUNTIF(K1:K35,"כמש"))*10 -> 18 | L36: =(COUNTIF(L1:L35,"הרצליה")+COUNTIF(L1:L35,"חיפה")+COUNTIF(L1:L35,"רמון")+COUNTIF(L1:L35,"ראש פינה")+COUNTIF(L1:L35,"ה.ב")) -> 1 | M36: =(COUNTIF(M1:M35,"כ")+COUNTIF(M1:M35,"כמ"))*6+(COUNTIF(M1:M35,"כש")+COUNTIF(M1:M35,"כמש"))*10 -> 22 | N36: =(COUNTIF(N1:N35,"הרצליה")+COUNTIF(N1:N35,"חיפה")+COUNTIF(N1:N35,"רמון")+COUNTIF(N1:N35,"ראש פינה")+COUNTIF(N1:N35,"ה.ב")) -> 5 | O36: =(COUNTIF(O1:O35,"כ")+COUNTIF(O1:O35,"כמ"))*6+(COUNTIF(O1:O35,"כש")+COUNTIF(O1:O35,"כמש"))*10 -> 36 | P36: =(COUNTIF(P1:P35,"הרצליה")+COUNTIF(P1:P35,"חיפה")+COUNTIF(P1:P35,"רמון")+COUNTIF(P1:P35,"ראש פינה")+COUNTIF(P1:P35,"ה.ב")) -> 0 | Q36: =(COUNTIF(Q1:Q35,"כ")+COUNTIF(Q1:Q35,"כמ"))*6+(COUNTIF(Q1:Q35,"כש")+COUNTIF(Q1:Q35,"כמש"))*10 -> 18 | R36: =(COUNTIF(R1:R35,"הרצליה")+COUNTIF(R1:R35,"חיפה")+COUNTIF(R1:R35,"רמון")+COUNTIF(R1:R35,"ראש פינה")+COUNTIF(R1:R35,"ה.ב")) -> 2 | S36: =(COUNTIF(S1:S35,"כ")+COUNTIF(S1:S35,"כמ"))*6+(COUNTIF(S1:S35,"כש")+COUNTIF(S1:S35,"כמש"))*10 -> 18 | T36: =(COUNTIF(T1:T35,"הרצליה")+COUNTIF(T1:T35,"חיפה")+COUNTIF(T1:T35,"רמון")+COUNTIF(T1:T35,"ראש פינה")+COUNTIF(T1:T35,"ה.ב")) -> 2 | U36: =(COUNTIF(U1:U35,"כ")+COUNTIF(U1:U35,"כמ"))*6+(COUNTIF(U1:U35,"כש")+COUNTIF(U1:U35,"כמש"))*10 -> 18 | V36: =(COUNTIF(V1:V35,"הרצליה")+COUNTIF(V1:V35,"חיפה")+COUNTIF(V1:V35,"רמון")+COUNTIF(V1:V35,"ראש פינה")+COUNTIF(V1:V35,"ה.ב")) -> 1 | W36: =(COUNTIF(W1:W35,"כ")+COUNTIF(W1:W35,"כמ"))*6+(COUNTIF(W1:W35,"כש")+COUNTIF(W1:W35,"כמש"))*10 -> 18 | X36: =(COUNTIF(X1:X35,"הרצליה")+COUNTIF(X1:X35,"חיפה")+COUNTIF(X1:X35,"רמון")+COUNTIF(X1:X35,"ראש פינה")+COUNTIF(X1:X35,"ה.ב")) -> 3 | Y36: =(COUNTIF(Y1:Y35,"כ")+COUNTIF(Y1:Y35,"כמ"))*6+(COUNTIF(Y1:Y35,"כש")+COUNTIF(Y1:Y35,"כמש"))*10 -> 50 | Z36: =(COUNTIF(Z1:Z35,"הרצליה")+COUNTIF(Z1:Z35,"חיפה")+COUNTIF(Z1:Z35,"רמון")+COUNTIF(Z1:Z35,"ראש פינה")+COUNTIF(Z1:Z35,"ה.ב")) -> 0 | AA36: =(COUNTIF(AA1:AA35,"כ")+COUNTIF(AA1:AA35,"כמ"))*6+(COUNTIF(AA1:AA35,"כש")+COUNTIF(AA1:AA35,"כמש"))*10 -> 0 | AB36: =(COUNTIF(AB1:AB35,"הרצליה")+COUNTIF(AB1:AB35,"חיפה")+COUNTIF(AB1:AB35,"רמון")+COUNTIF(AB1:AB35,"ראש פינה")+COUNTIF(AB1:AB35,"ה.ב")) -> 1 | AC36: =(COUNTIF(AC1:AC35,"כ")+COUNTIF(AC1:AC35,"כמ"))*6+(COUNTIF(AC1:AC35,"כש")+COUNTIF(AC1:AC35,"כמש"))*10 -> 30 | AD36: =(COUNTIF(AD1:AD35,"הרצליה")+COUNTIF(AD1:AD35,"חיפה")+COUNTIF(AD1:AD35,"רמון")+COUNTIF(AD1:AD35,"ראש פינה")+COUNTIF(AD1:AD35,"ה.ב")) -> 0 | AE36: =(COUNTIF(AE1:AE35,"כ")+COUNTIF(AE1:AE35,"כמ"))*6+(COUNTIF(AE1:AE35,"כש")+COUNTIF(AE1:AE35,"כמש"))*10 -> 36 | AF36: =(COUNTIF(AF1:AF35,"הרצליה")+COUNTIF(AF1:AF35,"חיפה")+COUNTIF(AF1:AF35,"רמון")+COUNTIF(AF1:AF35,"ראש פינה")+COUNTIF(AF1:AF35,"ה.ב")) -> 0 | AG36: =(COUNTIF(AG1:AG35,"כ")+COUNTIF(AG1:AG35,"כמ"))*6+(COUNTIF(AG1:AG35,"כש")+COUNTIF(AG1:AG35,"כמש"))*10 -> 40 | AH36: =(COUNTIF(AH1:AH35,"הרצליה")+COUNTIF(AH1:AH35,"חיפה")+COUNTIF(AH1:AH35,"רמון")+COUNTIF(AH1:AH35,"ראש פינה")+COUNTIF(AH1:AH35,"ה.ב")) -> 2 | AI36: =(COUNTIF(AI1:AI35,"כ")+COUNTIF(AI1:AI35,"כמ"))*6+(COUNTIF(AI1:AI35,"כש")+COUNTIF(AI1:AI35,"כמש"))*10 -> 30 | AJ36: =(COUNTIF(AJ1:AJ35,"הרצליה")+COUNTIF(AJ1:AJ35,"חיפה")+COUNTIF(AJ1:AJ35,"רמון")+COUNTIF(AJ1:AJ35,"ראש פינה")+COUNTIF(AJ1:AJ35,"ה.ב")) -> 2 | AK36: =(COUNTIF(AK1:AK35,"כ")+COUNTIF(AK1:AK35,"כמ"))*6+(COUNTIF(AK1:AK35,"כש")+COUNTIF(AK1:AK35,"כמש"))*10 -> 18 | AL36: =(COUNTIF(AL1:AL35,"הרצליה")+COUNTIF(AL1:AL35,"חיפה")+COUNTIF(AL1:AL35,"רמון")+COUNTIF(AL1:AL35,"ראש פינה")+COUNTIF(AL1:AL35,"ה.ב")) -> 0 | AM36: =(COUNTIF(AM1:AM35,"כ")+COUNTIF(AM1:AM35,"כמ"))*6+(COUNTIF(AM1:AM35,"כש")+COUNTIF(AM1:AM35,"כמש"))*10 -> 24 | AN36: =(COUNTIF(AN1:AN35,"הרצליה")+COUNTIF(AN1:AN35,"חיפה")+COUNTIF(AN1:AN35,"רמון")+COUNTIF(AN1:AN35,"ראש פינה")+COUNTIF(AN1:AN35,"ה.ב")) -> 1 | AO36: =(COUNTIF(AO1:AO35,"כ")+COUNTIF(AO1:AO35,"כמ"))*6+(COUNTIF(AO1:AO35,"כש")+COUNTIF(AO1:AO35,"כמש"))*10 -> 18 | AT36: יום | AW36: =COUNTIF(AX4:AX35,"י")+COUNTIF(AX4:AX35,"Y")+COUNTIF(AX4:AX35,"2") -> 8 | AY36: =COUNTIF(AZ4:AZ35,"י")+COUNTIF(AZ4:AZ35,"Y")+COUNTIF(AZ4:AZ35,"2") -> 5 | BA36: =COUNTIF(BB4:BB35,"י")+COUNTIF(BB4:BB35,"Y")+COUNTIF(BB4:BB35,"2") -> 8 | BC36: =COUNTIF(BD4:BD35,"י")+COUNTIF(BD4:BD35,"Y")+COUNTIF(BD4:BD35,"2") -> 8 | BE36: =COUNTIF(BF4:BF35,"י")+COUNTIF(BF4:BF35,"Y")+COUNTIF(BF4:BF35,"2") -> 3 | BG36: =COUNTIF(BH4:BH35,"י")+COUNTIF(BH4:BH35,"Y")+COUNTIF(BH4:BH35,"2") -> 6 | BI36: =COUNTIF(BJ4:BJ35,"י")+COUNTIF(BJ4:BJ35,"Y")+COUNTIF(BJ4:BJ35,"2") -> 6 | BK36: =COUNTIF(BL4:BL35,"י")+COUNTIF(BL4:BL35,"Y")+COUNTIF(BL4:BL35,"2") -> 4 | BM36: =COUNTIF(BN4:BN35,"י")+COUNTIF(BN4:BN35,"Y")+COUNTIF(BN4:BN35,"2") -> 7 | BO36: =COUNTIF(BP4:BP35,"י")+COUNTIF(BP4:BP35,"Y")+COUNTIF(BP4:BP35,"2") -> 8 | BQ36: =COUNTIF(BR4:BR35,"י")+COUNTIF(BR4:BR35,"Y")+COUNTIF(BR4:BR35,"2") -> 0 | BS36: =COUNTIF(BT4:BT35,"י")+COUNTIF(BT4:BT35,"Y")+COUNTIF(BT4:BT35,"2") -> 3 | BU36: =COUNTIF(BV4:BV35,"י")+COUNTIF(BV4:BV35,"Y")+COUNTIF(BV4:BV35,"2") -> 7 | BW36: =COUNTIF(BX4:BX35,"י")+COUNTIF(BX4:BX35,"Y")+COUNTIF(BX4:BX35,"2") -> 5 | BY36: =COUNTIF(BZ4:BZ35,"י")+COUNTIF(BZ4:BZ35,"Y")+COUNTIF(BZ4:BZ35,"2") -> 8 | CA36: =COUNTIF(CB4:CB35,"י")+COUNTIF(CB4:CB35,"Y")+COUNTIF(CB4:CB35,"2") -> 11 | CC36: שעות נומינלי
C37: שנתי | D37: =D36 -> 1 | E37: =E36 -> 18 | F37: =F36 -> 2 | G37: =G36 -> 22 | H37: =H36 -> 0 | I37: =I36 -> 18 | J37: =J36 -> 1 | K37: =K36 -> 18 | ... AC37: =AC36 -> 30 | AF37: =AF36 -> 0 | AG37: =AG36 -> 40 | AH37: =AH36 -> 2 | AI37: =AI36 -> 30 | AJ37: =AJ36 -> 2 | AK37: =AK36 -> 18 | AL37: =AL36 -> 0 | AM37: =AM36 -> 24 | ... AO37: =AO36 -> 18 | AT37: לילה | AW37: =COUNTIF(AX4:AX35,"ל")+COUNTIF(AX4:AX35,"L")+COUNTIF(AX4:AX35,"ל2") -> 6 | AY37: =COUNTIF(AZ4:AZ35,"ל")+COUNTIF(AZ4:AZ35,"L")+COUNTIF(AZ4:AZ35,"ל2") -> 8 | BA37: =COUNTIF(BB4:BB35,"ל")+COUNTIF(BB4:BB35,"L")+COUNTIF(BB4:BB35,"ל2") -> 7 | BC37: =COUNTIF(BD4:BD35,"ל")+COUNTIF(BD4:BD35,"L")+COUNTIF(BD4:BD35,"ל2") -> 10 | BE37: =COUNTIF(BF4:BF35,"ל")+COUNTIF(BF4:BF35,"L")+COUNTIF(BF4:BF35,"ל2") -> 3 | BG37: =COUNTIF(BH4:BH35,"ל")+COUNTIF(BH4:BH35,"L")+COUNTIF(BH4:BH35,"ל2") -> 8 | BI37: =COUNTIF(BJ4:BJ35,"ל")+COUNTIF(BJ4:BJ35,"L")+COUNTIF(BJ4:BJ35,"ל2") -> 9 | BK37: =COUNTIF(BL4:BL35,"ל")+COUNTIF(BL4:BL35,"L")+COUNTIF(BL4:BL35,"ל2") -> 5 | BM37: =COUNTIF(BN4:BN35,"ל")+COUNTIF(BN4:BN35,"L")+COUNTIF(BN4:BN35,"ל2") -> 9 | BO37: =COUNTIF(BP4:BP35,"ל")+COUNTIF(BP4:BP35,"L")+COUNTIF(BP4:BP35,"ל2") -> 8 | BQ37: =COUNTIF(BR4:BR35,"ל")+COUNTIF(BR4:BR35,"L")+COUNTIF(BR4:BR35,"ל2") -> 1 | BS37: =COUNTIF(BT4:BT35,"ל")+COUNTIF(BT4:BT35,"L")+COUNTIF(BT4:BT35,"ל2") -> 11 | BU37: =COUNTIF(BV4:BV35,"ל")+COUNTIF(BV4:BV35,"L")+COUNTIF(BV4:BV35,"ל2") -> 7 | BW37: =COUNTIF(BX4:BX35,"ל")+COUNTIF(BX4:BX35,"L")+COUNTIF(BX4:BX35,"ל2") -> 9 | BY37: =COUNTIF(BZ4:BZ35,"ל")+COUNTIF(BZ4:BZ35,"L")+COUNTIF(BZ4:BZ35,"ל2") -> 8 | CA37: =COUNTIF(CB4:CB35,"ל")+COUNTIF(CB4:CB35,"L")+COUNTIF(CB4:CB35,"ל2") -> 7
AW38: =(AW36*12)+(AW37*12)+(COUNTIF(AX4:AX35,"ק")*8)+(COUNTIF(AX4:AX35,"ח")*8)+(COUNTIF(AX4:AX35,"מ")*8)+(COUNTIF(AX4:AX35,"מיל")*8) -> 176 | AY38: =(AY36*12)+(AY37*12)+(COUNTIF(AZ4:AZ35,"ק")*8)+(COUNTIF(AZ4:AZ35,"ח")*8)+(COUNTIF(AZ4:AZ35,"מ")*8)+(COUNTIF(AZ4:AZ35,"מיל")*8) -> 172 | BA38: =(BA36*12)+(BA37*12)+(COUNTIF(BB4:BB35,"ק")*8)+(COUNTIF(BB4:BB35,"ח")*8)+(COUNTIF(BB4:BB35,"מ")*8)+(COUNTIF(BB4:BB35,"מיל")*8) -> 180 | BC38: =(BC36*12)+(BC37*12)+(COUNTIF(BD4:BD35,"ק")*8)+(COUNTIF(BD4:BD35,"ח")*8)+(COUNTIF(BD4:BD35,"מ")*8)+(COUNTIF(BD4:BD35,"מיל")*8) -> 216 | BE38: =(BE36*12)+(BE37*12)+(COUNTIF(BF4:BF35,"ק")*8)+(COUNTIF(BF4:BF35,"ח")*8)+(COUNTIF(BF4:BF35,"מ")*8)+(COUNTIF(BF4:BF35,"מיל")*8) -> 152 | BG38: =(BG36*12)+(BG37*12)+(COUNTIF(BH4:BH35,"ק")*8)+(COUNTIF(BH4:BH35,"ח")*8)+(COUNTIF(BH4:BH35,"מ")*8)+(COUNTIF(BH4:BH35,"מיל")*8) -> 168 | BI38: =(BI36*12)+(BI37*12)+(COUNTIF(BJ4:BJ35,"ק")*8)+(COUNTIF(BJ4:BJ35,"ח")*8)+(COUNTIF(BJ4:BJ35,"מ")*8)+(COUNTIF(BJ4:BJ35,"מיל")*8) -> 180 | BK38: =(BK36*12)+(BK37*12)+(COUNTIF(BL4:BL35,"ק")*8)+(COUNTIF(BL4:BL35,"ח")*8)+(COUNTIF(BL4:BL35,"מ")*8)+(COUNTIF(BL4:BL35,"מיל")*8) -> 204 | BM38: =(BM36*12)+(BM37*12)+(COUNTIF(BN4:BN35,"ק")*8)+(COUNTIF(BN4:BN35,"ח")*8)+(COUNTIF(BN4:BN35,"מ")*8)+(COUNTIF(BN4:BN35,"מיל")*8) -> 232 | BO38: =(BO36*12)+(BO37*12)+(COUNTIF(BP4:BP35,"ק")*8)+(COUNTIF(BP4:BP35,"ח")*8)+(COUNTIF(BP4:BP35,"מ")*8)+(COUNTIF(BP4:BP35,"מיל")*8) -> 192 | BQ38: =(BQ36*12)+(BQ37*12)+(COUNTIF(BR4:BR35,"ק")*8)+(COUNTIF(BR4:BR35,"ח")*8)+(COUNTIF(BR4:BR35,"מ")*8)+(COUNTIF(BR4:BR35,"מיל")*8) -> 156 | BS38: =(BS36*12)+(BS37*12)+(COUNTIF(BT4:BT35,"ק")*8)+(COUNTIF(BT4:BT35,"ח")*8)+(COUNTIF(BT4:BT35,"מ")*8)+(COUNTIF(BT4:BT35,"מיל")*8) -> 176 | BU38: =(BU36*12)+(BU37*12)+(COUNTIF(BV4:BV35,"ק")*8)+(COUNTIF(BV4:BV35,"ח")*8)+(COUNTIF(BV4:BV35,"מ")*8)+(COUNTIF(BV4:BV35,"מיל")*8) -> 168 | BW38: =(BW36*12)+(BW37*12)+(COUNTIF(BX4:BX35,"ק")*8)+(COUNTIF(BX4:BX35,"ח")*8)+(COUNTIF(BX4:BX35,"מ")*8)+(COUNTIF(BX4:BX35,"מיל")*8) -> 176 | BY38: =(BY36*12)+(BY37*12)+(COUNTIF(BZ4:BZ35,"ק")*8)+(COUNTIF(BZ4:BZ35,"ח")*8)+(COUNTIF(BZ4:BZ35,"מ")*8)+(COUNTIF(BZ4:BZ35,"מיל")*8) -> 192 | CA38: =(CA36*12)+(CA37*12)+(COUNTIF(CB4:CB35,"ק")*8)+(COUNTIF(CB4:CB35,"ח")*8)+(COUNTIF(CB4:CB35,"מ")*8)+(COUNTIF(CB4:CB35,"מיל")*8) -> 216 | CC38: 168
AW39: =AW38-CC38 -> 8 | AY39: =AY38-CC38 -> 4 | BA39: =BA38-CC38 -> 12 | BC39: =BC38-CC38 -> 48 | BE39: =BE38-CC38 -> -16 | BG39: =BG38-CC38 -> 0 | BI39: =BI38-CC38 -> 12 | BK39: =BK38-CC38 -> 36 | BM39: =BM38-CC38 -> 64 | BO39: =BO38-CC38 -> 24 | BQ39: =BQ38-CC38 -> -12 | BS39: =BS38-CC38 -> 8 | BU39: =BU38-CC38 -> 0 | BW39: =BW38-CC38 -> 8 | BY39: =BY38-CC38 -> 24 | CA39: =CA38-CC38 -> 48 | CC39: חוסר לנומינלי

Sheet פברואר
A1: פברואר שבת-אדר | AT1: 2 | AW1: עובדי משמרת | CC1: 2
D2: מדור פיקוד | X2: רמ"ד פיקוד | Z2: רמ"ח | AF2: רמ"ד ת.מסלול | AH2: מדור תאורת מסלולים | AP2: הערות | AR2: רכבים | AW2: משמרת 1 | BE2: משמרת 2 | BM2: משמרת 3 | BU2: משמרת 4 | CF2: כמות עובדים | CH2: עבודות מסלולים | CJ2: הערות
D3: קובי דניאלי | F3: תומר סער | H3: עמית נדל | J3: דניאל סויסה | L3: מיכאל דניאל | N3: יואב ברדוגו | P3: דוד מהלו | R3: אלון איברנדי | T3: סהר קובה | V3: שגיב בניתה | X3: אבי מנור | Z3: מוטי חלפון | AB3: איציק אפרמשוילי | AD3: אבי שמואלי | AF3: שמוליק פוגל | AH3: אלי פבלוב | AJ3: ראובן בוזנח | AL3: גיטאו אבבה | AN3: תומר ליבוביץ | AW3: שתה בירו | AY3: ליאור אברהם | BA3: ברק מור | BC3: אדם כהן | BE3: מרבי קריכלי | BG3: ירון טייב | BI3: עומרי סלמן | BK3: גבריאל וכטרמן | BM3: שלומי חן | BO3: אור שלו | BQ3: עומר גבע | BS3: איציק חוחא | BW3: שי סואד | BY3: דור שרוני | CA3: אורגד שניאור
D4: =HYPERLINK("maiLto:" & מיילים!B9 & "?subject=" & מיילים!G$3 & "&body=" & מיילים!H$3,"עדכון במייל") -> עדכון במייל | F4: =HYPERLINK("maiLto:" & מיילים!B10 & "?subject=" & מיילים!G$3 & "&body=" & מיילים!H$3,"עדכון במייל") -> עדכון במייל | H4: =HYPERLINK("maiLto:" & מיילים!B11 & "?subject=" & מיילים!G$3 & "&body=" & מיילים!H$3,"עדכון במייל") -> עדכון במייל | J4: =HYPERLINK("maiLto:" & מיילים!B12 & "?subject=" & מיילים!G$3 & "&body=" & מיילים!H$3,"עדכון במייל") -> עדכון במייל | L4: =HYPERLINK("maiLto:" & מיילים!B13 & "?subject=" & מיילים!G$3 & "&body=" & מיילים!H$3,"עדכון במייל") -> עדכון במייל | N4: =HYPERLINK("maiLto:" & מיילים!B6 & "?subject=" & מיילים!G$3 & "&body=" & מיילים!H$3,"עדכון במייל") -> עדכון במייל | P4: =HYPERLINK("maiLto:" & מיילים!B14 & "?subject=" & מיילים!G$3 & "&body=" & מיילים!H$3,"עדכון במייל") -> עדכון במייל | R4: =HYPERLINK("maiLto:" & מיילים!B34 & "?subject=" & מיילים!G$3 & "&body=" & מיילים!H$3,"עדכון במייל") -> עדכון במייל | T4: =HYPERLINK("maiLto:" & מיילים!B36 & "?subject=" & מיילים!G$3 & "&body=" & מיילים!H$3,"עדכון במייל") -> עדכון במייל | V4: =HYPERLINK("maiLto:" & מיילים!B35 & "?subject=" & מיילים!G$3 & "&body=" & מיילים!H$3,"עדכון במייל") -> עדכון במייל | X4: =HYPERLINK("maiLto:" & מיילים!B12 & "?subject=" & מיילים!G$3 & "&body=" & מיילים!H$3,"עדכון במייל") -> עדכון במייל | Z4: =HYPERLINK("maiLto:" & מיילים!B28 & "?subject=" & מיילים!G$3 & "&body=" & מיילים!H$3,"עדכון במייל") -> עדכון במייל | AB4: =HYPERLINK("maiLto:" & מיילים!B7 & "?subject=" & מיילים!G$3 & "&body=" & מיילים!H$3,"עדכון במייל") -> עדכון במייל | AD4: =HYPERLINK("maiLto:" & מיילים!B8 & "?subject=" & מיילים!I$3 & "&body=" & מיילים!J$3,"עדכון במייל") -> עדכון במייל | AF4: =HYPERLINK("maiLto:" & מיילים!B5 & "?subject=" & מיילים!I$3 & "&body=" & מיילים!J$3,"עדכון במייל") -> עדכון במייל | AH4: =HYPERLINK("maiLto:" & מיילים!B15 & "?subject=" & מיילים!G$3 & "&body=" & מיילים!H$3,"עדכון במייל") -> עדכון במייל | AJ4: =HYPERLINK("maiLto:" & מיילים!B17 & "?subject=" & מיילים!G$3 & "&body=" & מיילים!H$3,"עדכון במייל") -> עדכון במייל | AL4: =HYPERLINK("maiLto:" & מיילים!B37 & "?subject=" & מיילים!G$3 & "&body=" & מיילים!H$3,"עדכון במייל") -> עדכון במייל | AN4: =HYPERLINK("maiLto:" & מיילים!B38 & "?subject=" & מיילים!G$3 & "&body=" & מיילים!H$3,"עדכון במייל") -> עדכון במייל | AR4: DMAX | AS4: Staria | AW4: =HYPERLINK("maiLto:" & מיילים!B18 & "?subject=" & מיילים!G$3 & "&body=" & מיילים!H$3,"עדכון במייל") -> עדכון במייל | AY4: =HYPERLINK("maiLto:" & מיילים!B20 & "?subject=" & מיילים!G$3 & "&body=" & מיילים!H$3,"עדכון במייל") -> עדכון במייל | BA4: =HYPERLINK("maiLto:" & מיילים!B31 & "?subject=" & מיילים!G$3 & "&body=" & מיילים!H$3,"עדכון במייל") -> עדכון במייל | BC4: =HYPERLINK("maiLto:" & מיילים!B32 & "?subject=" & מיילים!G$3 & "&body=" & מיילים!H$3,"עדכון במייל") -> עדכון במייל | BE4: =HYPERLINK("maiLto:" & מיילים!B22 & "?subject=" & מיילים!G$3 & "&body=" & מיילים!H$3,"עדכון במייל") -> עדכון במייל | BG4: =HYPERLINK("maiLto:" & מיילים!B23 & "?subject=" & מיילים!G$3 & "&body=" & מיילים!H$3,"עדכון במייל") -> עדכון במייל | BI4: =HYPERLINK("maiLto:" & מיילים!B24 & "?subject=" & מיילים!G$3 & "&body=" & מיילים!H$3,"עדכון במייל") -> עדכון במייל | BK4: =HYPERLINK("maiLto:" & מיילים!B25 & "?subject=" & מיילים!G$3 & "&body=" & מיילים!H$3,"עדכון במייל") -> עדכון במייל | BM4: =HYPERLINK("maiLto:" & מיילים!B26 & "?subject=" & מיילים!G$3 & "&body=" & מיילים!H$3,"עדכון במייל") -> עדכון במייל | BO4: =HYPERLINK("maiLto:" & מיילים!R19 & "?subject=" & מיילים!W$3 & "&body=" & מיילים!X$3,"עדכון במייל") -> עדכון במייל | BQ4: =HYPERLINK("maiLto:" & מיילים!P21 & "?subject=" & מיילים!U$3 & "&body=" & מיילים!V$3,"עדכון במייל") -> עדכון במייל | BS4: =HYPERLINK("maiLto:" & מיילים!B27 & "?subject=" & מיילים!G$3 & "&body=" & מיילים!H$3,"עדכון במייל") -> עדכון במייל | BU4: =HYPERLINK("maiLto:" & מיילים!B28 & "?subject=" & מיילים!G$3 & "&body=" & מיילים!H$3,"עדכון במייל") -> עדכון במייל | BW4: =HYPERLINK("maiLto:" & מיילים!B29 & "?subject=" & מיילים!G$3 & "&body=" & מיילים!H$3,"עדכון במייל") -> עדכון במייל | BY4: =HYPERLINK("maiLto:" & מיילים!B30 & "?subject=" & מיילים!G$3 & "&body=" & מיילים!H$3,"עדכון במייל") -> עדכון במייל | CA4: =HYPERLINK("maiLto:" & מיילים!P33 & "?subject=" & מיילים!U$3 & "&body=" & מיילים!V$3,"עדכון במייל") -> עדכון במייל | CF4: יום | CG4: לילה | CH4: עבודות יום | CI4: עבודות לילה
A5: 1 | B5: יום א | C5: 6 | E5: כ | J5: מיל | V5: מיל | AL5: ק | AO5: כמ | AT5: 1 | AU5: יום א | AV5: 6 | AX5: ל | AZ5: ל | BB5: ל | BD5: ל | BF5: י | BH5: י | BJ5: י | BL5: ח | BT5: ח | CC5: 1 | CD5: יום א | CE5: 5 | CF5: =COUNTIF(AX5:CB5,"י")+COUNTIF(AX5:CB5,"Y")+COUNTIF(AX5:CB5,"2") -> 3 | CG5: =COUNTIF(AW5:CB5,"ל")+COUNTIF(AW5:CB5,"L")+COUNTIF(AW5:CB5,"ל2") -> 4 | CI5: מסלול
A6: 2 | B6: יום ב | F6: ק | G6: כמ | H6: ק | J6: מיל | V6: מיל | AC6: כ | AH6: ק | AN6: מיל | AP6: ראש השנה לאילנות | AT6: 2 | AU6: יום ב | BF6: ל | BH6: ל | BJ6: ל | BL6: ח | BN6: י | BP6: ח | BR6: י | BT6: ח | CC6: 2 | CD6: יום ב | CF6: =COUNTIF(AX6:CB6,"י")+COUNTIF(AX6:CB6,"Y")+COUNTIF(AX6:CB6,"2") -> 2 | CG6: =COUNTIF(AW6:CB6,"ל")+COUNTIF(AW6:CB6,"L")+COUNTIF(AW6:CB6,"ל2") -> 3
A7: 3 | B7: יום ג | F7: חיפה | H7: רמון | J7: מיל | L7: רמון | P7: רמון | R7: חיפה | T7: חיפה | V7: מיל | Y7: כמ | AC7: כ | AD7: DCCMS | AL7: חיפה | AN7: מיל | AT7: 3 | AU7: יום ג | BB7: ח | BN7: ל | BP7: מ | BR7: ל | BT7: ח | BX7: י | BZ7: י | CB7: י | CC7: 3 | CD7: יום ג | CF7: =COUNTIF(AX7:CB7,"י")+COUNTIF(AX7:CB7,"Y")+COUNTIF(AX7:CB7,"2") -> 3 | CG7: =COUNTIF(AW7:CB7,"ל")+COUNTIF(AW7:CB7,"L")+COUNTIF(AW7:CB7,"ל2") -> 2 | CH7: מסלול | CI7: מסלול
A8: 4 | B8: יום ד | D8: DCRS | F8: PBB | G8: כמ | H8: רמון | J8: מיל | L8: רמון | O8: כ | P8: רמון | R8: DCRS | T8: PBB | V8: מיל | X8: ראש פינה | AB8: ראש פינה | AN8: מיל | AT8: 4 | AU8: יום ד | AX8: י | AZ8: י | BB8: י | BD8: י | BF8: ח | BT8: ח | BX8: ל | BZ8: ל | CB8: ל | CC8: 4 | CD8: יום ד | CF8: =COUNTIF(AX8:CB8,"י")+COUNTIF(AX8:CB8,"Y")+COUNTIF(AX8:CB8,"2") -> 4 | CG8: =COUNTIF(AW8:CB8,"ל")+COUNTIF(AW8:CB8,"L")+COUNTIF(AW8:CB8,"ל2") -> 3
A9: 5 | B9: יום ה | D9: DCRS | F9: PBB | H9: רמון | J9: מיל | L9: רמון | N9: ח | P9: רמון | R9: DCRS | U9: כ | V9: מיל | AE9: כמ | AF9: רת"א | AJ9: ח | AN9: מיל | AP9: פיקוח רת"א | AS9: פוגל | AT9: 5 | AU9: יום ה | AX9: ל | AZ9: ל | BB9: ל | BD9: ל | BF9: י | BH9: י | BJ9: פ | BL9: ח | BT9: ח | CC9: 5 | CD9: יום ה | CF9: =COUNTIF(AX9:CB9,"י")+COUNTIF(AX9:CB9,"Y")+COUNTIF(AX9:CB9,"2") -> 2 | CG9: =COUNTIF(AW9:CB9,"ל")+COUNTIF(AW9:CB9,"L")+COUNTIF(AW9:CB9,"ל2") -> 4
A10: 6 | B10: יום ו | J10: מיל | N10: פ | V10: מיל | Y10: כש | AG10: כמש | AN10: מיל | AT10: 6 | AU10: יום ו | BF10: ל | BH10: ל | BJ10: ל | BL10: ל | BN10: י | BP10: ח | BR10: י | BT10: פ | CC10: 6 | CD10: יום ו | CF10: =COUNTIF(AX10:CB10,"י")+COUNTIF(AX10:CB10,"Y")+COUNTIF(AX10:CB10,"2") -> 2 | CG10: =COUNTIF(AW10:CB10,"ל")+COUNTIF(AW10:CB10,"L")+COUNTIF(AW10:CB10,"ל2") -> 4
A11: 7 | B11: שבת | J11: מיל | N11: פ | V11: מיל | Y11: כש | AG11: כמש | AN11: מיל | AT11: 7 | AU11: שבת | BN11: ל | BP11: ל | BR11: ל | BT11: פ | BX11: י | BZ11: י | CB11: י | CC11: 7 | CD11: שבת | CF11: =COUNTIF(AX11:CB11,"י")+COUNTIF(AX11:CB11,"Y")+COUNTIF(AX11:CB11,"2") -> 3 | CG11: =COUNTIF(AW11:CB11,"ל")+COUNTIF(AW11:CB11,"L")+COUNTIF(AW11:CB11,"ל2") -> 3
A12: 8 | B12: יום א | C12: 7 | D12: DCRS | F12: AVDGS | J12: מיל | L12: PBB | N12: ח | R12: DCRS | T12: PBB | V12: מיל | AC12: כ | AK12: כמ | AL12: ק | AN12: מיל | AT12: 8 | AU12: יום א | AV12: 7 | AX12: י | AZ12: ח | BB12: ח | BD12: י | BT12: ח | BX12: ל | BZ12: ל | CB12: ל | CC12: 8 | CD12: יום א | CE12: 6 | CF12: =COUNTIF(AX12:CB12,"י")+COUNTIF(AX12:CB12,"Y")+COUNTIF(AX12:CB12,"2") -> 2 | CG12: =COUNTIF(AW12:CB12,"ל")+COUNTIF(AW12:CB12,"L")+COUNTIF(AW12:CB12,"ל2") -> 3 | CI12: מסלול
A13: 9 | B13: יום ב | D13: DCRS | F13: AVDGS | H13: ח | J13: מיל | L13: PBB | N13: ה.ב | R13: DCRS | V13: מיל | X13: ה.ב | AC13: כ | AK13: כמ | AN13: מיל | AT13: 9 | AU13: יום ב | AX13: ל | AZ13: ל | BB13: ל | BD13: ל | BF13: ח | BH13: י | BJ13: י | BL13: י | BT13: ח | CC13: 9 | CD13: יום ב | CF13: =COUNTIF(AX13:CB13,"י")+COUNTIF(AX13:CB13,"Y")+COUNTIF(AX13:CB13,"2") -> 3 | CG13: =COUNTIF(AW13:CB13,"ל")+COUNTIF(AW13:CB13,"L")+COUNTIF(AW13:CB13,"ל2") -> 4 | CI13: מסלול
A14: 10 | B14: יום ג | D14: DCRS | F14: AVDGS | H14: ח | J14: מיל | Q14: כ | R14: DCRS | V14: מיל | X14: ראש פינה | Z14: ראש פינה | AF14: ראש פינה | AM14: כמ | AN14: מיל | AT14: 10 | AU14: יום ג | BF14: ל | BH14: ל | BJ14: ל | BL14: ל | BN14: י | BP14: י | BR14: י | BT14: ח | CC14: 10 | CD14: יום ג | CF14: =COUNTIF(AX14:CB14,"י")+COUNTIF(AX14:CB14,"Y")+COUNTIF(AX14:CB14,"2") -> 3 | CG14: =COUNTIF(AW14:CB14,"ל")+COUNTIF(AW14:CB14,"L")+COUNTIF(AW14:CB14,"ל2") -> 4 | CH14: מסלול | CI14: מסלול
A15: 11 | B15: יום ד | F15: AVDGS | J15: מיל | L15: PBB | U15: כ | V15: מיל | AE15: כמ | AH15: DCCMS | AN15: מיל | AT15: 11 | AU15: יום ד | BD15: Y | BN15: ל | BP15: ל | BR15: ל | BT15: ח | BX15: י | BZ15: י | CB15: י | CC15: 11 | CD15: יום ד | CF15: =COUNTIF(AX15:CB15,"י")+COUNTIF(AX15:CB15,"Y")+COUNTIF(AX15:CB15,"2") -> 4 | CG15: =COUNTIF(AW15:CB15,"ל")+COUNTIF(AW15:CB15,"L")+COUNTIF(AW15:CB15,"ל2") -> 3 | CI15: מסלול
A16: 12 | B16: יום ה | F16: AVDGS | I16: כ | J16: מיל | L16: PBB | R16: סיבים | T16: PBB | V16: מיל | AH16: ח | AM16: כמ | AN16: מיל | AT16: 12 | AU16: יום ה | AX16: י | AZ16: י | BB16: י | BD16: י | BN16: L | BT16: ח | BX16: ל | BZ16: ח | CB16: ל | CC16: 12 | CD16: יום ה | CF16: =COUNTIF(AX16:CB16,"י")+COUNTIF(AX16:CB16,"Y")+COUNTIF(AX16:CB16,"2") -> 4 | CG16: =COUNTIF(AW16:CB16,"ל")+COUNTIF(AW16:CB16,"L")+COUNTIF(AW16:CB16,"ל2") -> 3
A17: 13 | B17: יום ו | J17: מיל | O17: כש | V17: מיל | AG17: כמש | AN17: מיל | AT17: 13 | AU17: יום ו | AX17: ל | AZ17: ל | BB17: ל | BD17: ל | BF17: י | BH17: י | BJ17: י | BL17: י | CC17: 13 | CD17: יום ו | CF17: =COUNTIF(AX17:CB17,"י")+COUNTIF(AX17:CB17,"Y")+COUNTIF(AX17:CB17,"2") -> 4 | CG17: =COUNTIF(AW17:CB17,"ל")+COUNTIF(AW17:CB17,"L")+COUNTIF(AW17:CB17,"ל2") -> 4
A18: 14 | B18: שבת | J18: מיל | O18: כש | V18: מיל | AG18: כמש | AN18: מיל | AT18: 14 | AU18: שבת | BF18: ל | BH18: ל | BJ18: ל | BL18: ל | BN18: פ | BP18: י | BR18: י | BT18: פ | CC18: 14 | CD18: שבת | CF18: =COUNTIF(AX18:CB18,"י")+COUNTIF(AX18:CB18,"Y")+COUNTIF(AX18:CB18,"2") -> 2 | CG18: =COUNTIF(AW18:CB18,"ל")+COUNTIF(AW18:CB18,"L")+COUNTIF(AW18:CB18,"ל2") -> 4 | CH18: מסלול
A19: 15 | B19: יום א | C19: 8 | E19: כ | F19: AVDGS | H19: מ | J19: מיל | L19: יוצא מוקדם | R19: ראש פינה | T19: ח | V19: מיל | AB19: ראש פינה | AD19: מ | AH19: ח | AK19: כמ | AL19: ק | AN19: מיל | AP19: ריענון מלגזה | AT19: 15 | AU19: יום א | AV19: 8 | BD19: Y | BN19: ל | BP19: ל | BR19: ל | BT19: ל | BX19: י | BZ19: י | CB19: י | CC19: 15 | CD19: יום א | CE19: 7 | CF19: =COUNTIF(AX19:CB19,"י")+COUNTIF(AX19:CB19,"Y")+COUNTIF(AX19:CB19,"2") -> 4 | CG19: =COUNTIF(AW19:CB19,"ל")+COUNTIF(AW19:CB19,"L")+COUNTIF(AW19:CB19,"ל2") -> 4 | CI19: מסלול | CJ19: ריענון מלגזה
A20: 16 | B20: יום ב | D20: DCRS | F20: AVDGS | H20: מ | J20: מיל | L20: E8 | N20: AVDGS | P20: תחנות | T20: E8 | V20: מיל | X20: שלטי עמדה | AC20: כ | AD20: מ | AL20: תחנות | AN20: מיל | AT20: 16 | AU20: יום ב | AX20: י | AZ20: ח | BB20: י | BD20: י | BX20: ל | BZ20: ל | CB20: ל | CC20: 16 | CD20: יום ב | CF20: =COUNTIF(AX20:CB20,"י")+COUNTIF(AX20:CB20,"Y")+COUNTIF(AX20:CB20,"2") -> 3 | CG20: =COUNTIF(AW20:CB20,"ל")+COUNTIF(AW20:CB20,"L")+COUNTIF(AW20:CB20,"ל2") -> 3
A21: 17 | B21: יום ג | D21: DCRS | F21: AVDGS | N21: שלטי עמדה | Q21: כמ | R21: DCRS | S21: כ | W21: כמ | Z21: ח | AN21: מיל | AP21: מנוף תאורת גישה 21 | AT21: 17 | AU21: יום ג | AX21: ל | AZ21: ל | BB21: ל | BD21: ח | BF21: י | BH21: י | BJ21: י | BL21: י | CC21: 17 | CD21: יום ג | CF21: =COUNTIF(AX21:CB21,"י")+COUNTIF(AX21:CB21,"Y")+COUNTIF(AX21:CB21,"2") -> 4 | CG21: =COUNTIF(AW21:CB21,"ל")+COUNTIF(AW21:CB21,"L")+COUNTIF(AW21:CB21,"ל2") -> 3
A22: 18 | B22: יום ד | D22: DCRS | E22: כ | F22: AVDGS | G22: כמ | H22: דס"ל | J22: מיל | N22: שלטי עמדה | P22: ראש פינה | R22: AVDGS | T22: ראש פינה | V22: AVDGS | Z22: ח | AB22: ראש פינה | AH22: DCCMS | AJ22: ראש פינה | AL22: דס"ל | AN22: מיל | AP22: בטיחות כללית | AT22: 18 | AU22: יום ד | BD22: ח | BF22: ל | BH22: ל | BJ22: ל | BL22: פ | BN22: י | BP22: י | BR22: ח | BT22: י | CC22: 18 | CD22: יום ד | CF22: =COUNTIF(AX22:CB22,"י")+COUNTIF(AX22:CB22,"Y")+COUNTIF(AX22:CB22,"2") -> 3 | CG22: =COUNTIF(AW22:CB22,"ל")+COUNTIF(AW22:CB22,"L")+COUNTIF(AW22:CB22,"ל2") -> 3 | CJ22: בטיחות כללית
A23: 19 | B23: יום ה | D23: חיפה | F23: AVDGS | J23: מיל | Q23: כמ | R23: DCRS | V23: מיל | Z23: ח | AE23: כ | AL23: חיפה | AN23: מיל | AP23: אסיפת עובדים- ועד | AT23: 19 | AU23: יום ה | BB23: מ | BD23: ח | BN23: ל | BP23: ל | BR23: ח | BT23: ל | BX23: מ | BZ23: י | CB23: י | CC23: 19 | CD23: יום ה | CF23: =COUNTIF(AX23:CB23,"י")+COUNTIF(AX23:CB23,"Y")+COUNTIF(AX23:CB23,"2") -> 2 | CG23: =COUNTIF(AW23:CB23,"ל")+COUNTIF(AW23:CB23,"L")+COUNTIF(AW23:CB23,"ל2") -> 3 | CJ23: אסיפת עובדים- ועד
A24: 20 | B24: יום ו | J24: מיל | V24: מיל | Y24: כש | Z24: ח | AE24: כמש | AH24: שישי | AL24: שישי | AN24: מיל | AP24: עבודות שישי | AT24: 20 | AU24: יום ו | AX24: י | AZ24: י | BB24: פ | BD24: פ | BJ24: L | BN24: L | BX24: ל | BZ24: ל | CB24: ל | CC24: 20 | CD24: יום ו | CF24: =COUNTIF(AX24:CB24,"י")+COUNTIF(AX24:CB24,"Y")+COUNTIF(AX24:CB24,"2") -> 2 | CG24: =COUNTIF(AW24:CB24,"ל")+COUNTIF(AW24:CB24,"L")+COUNTIF(AW24:CB24,"ל2") -> 5 | CJ24: עבודות שישי
A25: 21 | B25: שבת | J25: מיל | V25: מיל | Y25: כש | Z25: ח | AI25: כמש | AN25: מיל | AT25: 21 | AU25: שבת | AX25: ל | AZ25: ל | BB25: פ | BD25: פ | BF25: י | BH25: י | BJ25: פ | BL25: י | BT25: L | CC25: 21 | CD25: שבת | CF25: =COUNTIF(AX25:CB25,"י")+COUNTIF(AX25:CB25,"Y")+COUNTIF(AX25:CB25,"2") -> 3 | CG25: =COUNTIF(AW25:CB25,"ל")+COUNTIF(AW25:CB25,"L")+COUNTIF(AW25:CB25,"ל2") -> 3
A26: 22 | B26: יום א | C26: 9 | D26: רמון | F26: רמון | J26: מיל | L26: ח | N26: רמון | P26: AVDGS | S26: כמ | T26: D4 | U26: כ | V26: מיל | X26: רמון | Z26: ח | AJ26: תחנות | AL26: ח | AN26: מיל | AT26: 22 | AU26: יום א | AV26: 9 | BB26: ח | BD26: ח | BF26: ל | BH26: ל | BJ26: ל | BL26: ל | BN26: פ | BP26: י | BR26: י | BT26: פ | CC26: 22 | CD26: יום א | CE26: 8 | CF26: =COUNTIF(AX26:CB26,"י")+COUNTIF(AX26:CB26,"Y")+COUNTIF(AX26:CB26,"2") -> 2 | CG26: =COUNTIF(AW26:CB26,"ל")+COUNTIF(AW26:CB26,"L")+COUNTIF(AW26:CB26,"ל2") -> 4 | CI26: מסלול
A27: 23 | B27: יום ב | D27: רמון | F27: רמון | H27: ח | J27: מיל | M27: כמ | N27: רמון | W27: כ | X27: רמון | Z27: ח | AD27: מ | AJ27: תחנות | AL27: ח | AN27: מיל | AT27: 23 | AU27: יום ב | BB27: מ | BD27: ח | BN27: ל | BP27: ל | BR27: ל | BT27: ל | BX27: י | BZ27: י | CB27: י | CC27: 23 | CD27: יום ב | CF27: =COUNTIF(AX27:CB27,"י")+COUNTIF(AX27:CB27,"Y")+COUNTIF(AX27:CB27,"2") -> 3 | CG27: =COUNTIF(AW27:CB27,"ל")+COUNTIF(AW27:CB27,"L")+COUNTIF(AW27:CB27,"ל2") -> 4 | CH27: מסלול | CI27: מסלול
A28: 24 | B28: יום ג | D28: רמון | F28: רמון | H28: ח | J28: מיל | M28: כמ | N28: רמון | R28: DCRS | W28: כ | X28: רמון | Z28: ח | AD28: מ | AN28: מיל | AP28: בטיחות כללית | AT28: 24 | AU28: יום ג | AX28: י | AZ28: י | BB28: מ | BD28: ח | BN28: L | BX28: ל | BZ28: ל | CB28: ל | CC28: 24 | CD28: יום ג | CF28: =COUNTIF(AX28:CB28,"י")+COUNTIF(AX28:CB28,"Y")+COUNTIF(AX28:CB28,"2") -> 2 | CG28: =COUNTIF(AW28:CB28,"ל")+COUNTIF(AW28:CB28,"L")+COUNTIF(AW28:CB28,"ל2") -> 4 | CH28: מסלול | CJ28: בטיחות כללית
A29: 25 | B29: יום ד | D29: רמון | F29: רמון | H29: EHDS | I29: כמ | J29: מיל | L29: D5 | N29: רמון | P29: CCR | R29: EHDS | S29: כ | T29: D5 | V29: מיל | X29: רמון | Z29: ח | AJ29: תחנות | AN29: מיל | AT29: 25 | AU29: יום ד | AX29: ח | AZ29: ל | BB29: ח | BD29: ח | BF29: י | BH29: י | BJ29: י | BL29: י | BX29: L | CC29: 25 | CD29: יום ד | CF29: =COUNTIF(AX29:CB29,"י")+COUNTIF(AX29:CB29,"Y")+COUNTIF(AX29:CB29,"2") -> 4 | CG29: =COUNTIF(AW29:CB29,"ל")+COUNTIF(AW29:CB29,"L")+COUNTIF(AW29:CB29,"ל2") -> 2
A30: 26 | B30: יום ה | D30: רמון | F30: רמון | H30: EHDS | I30: כמ | J30: מיל | L30: EHDS | M30: כ | N30: רמון | P30: AVDGS | V30: מיל | X30: רמון | Z30: ח | AJ30: תחנות | AN30: מיל | AT30: 26 | AU30: יום ה | BB30: ח | BD30: ח | BF30: ל | BH30: ל | BJ30: ח | BL30: ל | BN30: י | BP30: ח | BR30: L | BT30: ח | CC30: 26 | CD30: יום ה | CF30: =COUNTIF(AX30:CB30,"י")+COUNTIF(AX30:CB30,"Y")+COUNTIF(AX30:CB30,"2") -> 1 | CG30: =COUNTIF(AW30:CB30,"ל")+COUNTIF(AW30:CB30,"L")+COUNTIF(AW30:CB30,"ל2") -> 4
A31: 27 | B31: יום ו | J31: מיל | O31: כש | Z31: ח | AI31: כמש | AN31: מיל | AT31: 27 | AU31: יום ו | BN31: ל | BP31: ל | BR31: ל | BT31: פ | BX31: פ | BZ31: י | CB31: י | CC31: 27 | CD31: יום ו | CF31: =COUNTIF(AX31:CB31,"י")+COUNTIF(AX31:CB31,"Y")+COUNTIF(AX31:CB31,"2") -> 2 | CG31: =COUNTIF(AW31:CB31,"ל")+COUNTIF(AW31:CB31,"L")+COUNTIF(AW31:CB31,"ל2") -> 3
A32: 28 | B32: שבת | J32: מיל | Z32: ח | AE32: כש | AI32: כמש | AN32: מיל | AT32: 28 | AU32: שבת | AX32: L | AZ32: י | BB32: פ | BD32: פ | BN32: L | BT32: ל2 | BX32: ל | BZ32: פ | CB32: Y | CC32: 28 | CD32: שבת | CF32: =COUNTIF(AX32:CB32,"י")+COUNTIF(AX32:CB32,"Y")+COUNTIF(AX32:CB32,"2") -> 2 | CG32: =COUNTIF(AW32:CB32,"ל")+COUNTIF(AW32:CB32,"L")+COUNTIF(AW32:CB32,"ל2") -> 4
D33: =(COUNTIF(D5:D32,"הרצליה")+COUNTIF(D5:D32,"חיפה")+COUNTIF(D5:D32,"רמון")+COUNTIF(D5:D32,"ראש פינה")+COUNTIF(D5:D32,"ה.ב")) -> 6 | E33: =(COUNTIF(E5:E32,"כ")+COUNTIF(E5:E32,"כמ"))*6+(COUNTIF(E5:E32,"כש")+COUNTIF(E5:E32,"כמש"))*10 -> 18 | F33: =(COUNTIF(F5:F32,"הרצליה")+COUNTIF(F5:F32,"חיפה")+COUNTIF(F5:F32,"רמון")+COUNTIF(F5:F32,"ראש פינה")+COUNTIF(F5:F32,"ה.ב")) -> 6 | G33: =(COUNTIF(G5:G32,"כ")+COUNTIF(G5:G32,"כמ"))*6+(COUNTIF(G5:G32,"כש")+COUNTIF(G5:G32,"כמש"))*10 -> 18 | H33: =(COUNTIF(H5:H32,"הרצליה")+COUNTIF(H5:H32,"חיפה")+COUNTIF(H5:H32,"רמון")+COUNTIF(H5:H32,"ראש פינה")+COUNTIF(H5:H32,"ה.ב")) -> 3 | I33: =(COUNTIF(I5:I32,"כ")+COUNTIF(I5:I32,"כמ"))*6+(COUNTIF(I5:I32,"כש")+COUNTIF(I5:I32,"כמש"))*10 -> 18 | J33: =(COUNTIF(J5:J32,"הרצליה")+COUNTIF(J5:J32,"חיפה")+COUNTIF(J5:J32,"רמון")+COUNTIF(J5:J32,"ראש פינה")+COUNTIF(J5:J32,"ה.ב")) -> 0 | K33: =(COUNTIF(K5:K32,"כ")+COUNTIF(K5:K32,"כמ"))*6+(COUNTIF(K5:K32,"כש")+COUNTIF(K5:K32,"כמש"))*10 -> 0 | L33: =(COUNTIF(L5:L32,"הרצליה")+COUNTIF(L5:L32,"חיפה")+COUNTIF(L5:L32,"רמון")+COUNTIF(L5:L32,"ראש פינה")+COUNTIF(L5:L32,"ה.ב")) -> 3 | M33: =(COUNTIF(M5:M32,"כ")+COUNTIF(M5:M32,"כמ"))*6+(COUNTIF(M5:M32,"כש")+COUNTIF(M5:M32,"כמש"))*10 -> 18 | N33: =(COUNTIF(N5:N32,"הרצליה")+COUNTIF(N5:N32,"חיפה")+COUNTIF(N5:N32,"רמון")+COUNTIF(N5:N32,"ראש פינה")+COUNTIF(N5:N32,"ה.ב")) -> 6 | O33: =(COUNTIF(O5:O32,"כ")+COUNTIF(O5:O32,"כמ"))*6+(COUNTIF(O5:O32,"כש")+COUNTIF(O5:O32,"כמש"))*10 -> 36 | P33: =(COUNTIF(P5:P32,"הרצליה")+COUNTIF(P5:P32,"חיפה")+COUNTIF(P5:P32,"רמון")+COUNTIF(P5:P32,"ראש פינה")+COUNTIF(P5:P32,"ה.ב")) -> 4 | Q33: =(COUNTIF(Q5:Q32,"כ")+COUNTIF(Q5:Q32,"כמ"))*6+(COUNTIF(Q5:Q32,"כש")+COUNTIF(Q5:Q32,"כמש"))*10 -> 18 | R33: =(COUNTIF(R5:R32,"הרצליה")+COUNTIF(R5:R32,"חיפה")+COUNTIF(R5:R32,"רמון")+COUNTIF(R5:R32,"ראש פינה")+COUNTIF(R5:R32,"ה.ב")) -> 2 | S33: =(COUNTIF(S5:S32,"כ")+COUNTIF(S5:S32,"כמ"))*6+(COUNTIF(S5:S32,"כש")+COUNTIF(S5:S32,"כמש"))*10 -> 18 | T33: =(COUNTIF(T5:T32,"הרצליה")+COUNTIF(T5:T32,"חיפה")+COUNTIF(T5:T32,"רמון")+COUNTIF(T5:T32,"ראש פינה")+COUNTIF(T5:T32,"ה.ב")) -> 2 | U33: =(COUNTIF(U5:U32,"כ")+COUNTIF(U5:U32,"כמ"))*6+(COUNTIF(U5:U32,"כש")+COUNTIF(U5:U32,"כמש"))*10 -> 18 | V33: =(COUNTIF(V5:V32,"הרצליה")+COUNTIF(V5:V32,"חיפה")+COUNTIF(V5:V32,"רמון")+COUNTIF(V5:V32,"ראש פינה")+COUNTIF(V5:V32,"ה.ב")) -> 0 | W33: =(COUNTIF(W5:W32,"כ")+COUNTIF(W5:W32,"כמ"))*6+(COUNTIF(W5:W32,"כש")+COUNTIF(W5:W32,"כמש"))*10 -> 18 | X33: =(COUNTIF(X5:X32,"הרצליה")+COUNTIF(X5:X32,"חיפה")+COUNTIF(X5:X32,"רמון")+COUNTIF(X5:X32,"ראש פינה")+COUNTIF(X5:X32,"ה.ב")) -> 8 | Y33: =(COUNTIF(Y5:Y32,"כ")+COUNTIF(Y5:Y32,"כמ"))*6+(COUNTIF(Y5:Y32,"כש")+COUNTIF(Y5:Y32,"כמש"))*10 -> 46 | Z33: =(COUNTIF(Z5:Z32,"הרצליה")+COUNTIF(Z5:Z32,"חיפה")+COUNTIF(Z5:Z32,"רמון")+COUNTIF(Z5:Z32,"ראש פינה")+COUNTIF(Z5:Z32,"ה.ב")) -> 1 | AA33: =(COUNTIF(AA5:AA32,"כ")+COUNTIF(AA5:AA32,"כמ"))*6+(COUNTIF(AA5:AA32,"כש")+COUNTIF(AA5:AA32,"כמש"))*10 -> 0 | AB33: =(COUNTIF(AB5:AB32,"הרצליה")+COUNTIF(AB5:AB32,"חיפה")+COUNTIF(AB5:AB32,"רמון")+COUNTIF(AB5:AB32,"ראש פינה")+COUNTIF(AB5:AB32,"ה.ב")) -> 3 | AC33: =(COUNTIF(AC5:AC32,"כ")+COUNTIF(AC5:AC32,"כמ"))*6+(COUNTIF(AC5:AC32,"כש")+COUNTIF(AC5:AC32,"כמש"))*10 -> 30 | AD33: =(COUNTIF(AD5:AD32,"הרצליה")+COUNTIF(AD5:AD32,"חיפה")+COUNTIF(AD5:AD32,"רמון")+COUNTIF(AD5:AD32,"ראש פינה")+COUNTIF(AD5:AD32,"ה.ב")) -> 0 | AE33: =(COUNTIF(AE5:AE32,"כ")+COUNTIF(AE5:AE32,"כמ"))*6+(COUNTIF(AE5:AE32,"כש")+COUNTIF(AE5:AE32,"כמש"))*10 -> 38 | AF33: =(COUNTIF(AF5:AF32,"הרצליה")+COUNTIF(AF5:AF32,"חיפה")+COUNTIF(AF5:AF32,"רמון")+COUNTIF(AF5:AF32,"ראש פינה")+COUNTIF(AF5:AF32,"ה.ב")) -> 1 | AG33: =(COUNTIF(AG5:AG32,"כ")+COUNTIF(AG5:AG32,"כמ"))*6+(COUNTIF(AG5:AG32,"כש")+COUNTIF(AG5:AG32,"כמש"))*10 -> 40 | AH33: =(COUNTIF(AH5:AH32,"הרצליה")+COUNTIF(AH5:AH32,"חיפה")+COUNTIF(AH5:AH32,"רמון")+COUNTIF(AH5:AH32,"ראש פינה")+COUNTIF(AH5:AH32,"ה.ב")) -> 0 | AI33: =(COUNTIF(AI5:AI32,"כ")+COUNTIF(AI5:AI32,"כמ"))*6+(COUNTIF(AI5:AI32,"כש")+COUNTIF(AI5:AI32,"כמש"))*10 -> 30 | AJ33: =(COUNTIF(AJ5:AJ32,"הרצליה")+COUNTIF(AJ5:AJ32,"חיפה")+COUNTIF(AJ5:AJ32,"רמון")+COUNTIF(AJ5:AJ32,"ראש פינה")+COUNTIF(AJ5:AJ32,"ה.ב")) -> 1 | AK33: =(COUNTIF(AK5:AK32,"כ")+COUNTIF(AK5:AK32,"כמ"))*6+(COUNTIF(AK5:AK32,"כש")+COUNTIF(AK5:AK32,"כמש"))*10 -> 18 | AL33: =(COUNTIF(AL5:AL32,"הרצליה")+COUNTIF(AL5:AL32,"חיפה")+COUNTIF(AL5:AL32,"רמון")+COUNTIF(AL5:AL32,"ראש פינה")+COUNTIF(AL5:AL32,"ה.ב")) -> 2 | AM33: =(COUNTIF(AM5:AM32,"כ")+COUNTIF(AM5:AM32,"כמ"))*6+(COUNTIF(AM5:AM32,"כש")+COUNTIF(AM5:AM32,"כמש"))*10 -> 12 | AN33: =(COUNTIF(AN5:AN32,"הרצליה")+COUNTIF(AN5:AN32,"חיפה")+COUNTIF(AN5:AN32,"רמון")+COUNTIF(AN5:AN32,"ראש פינה")+COUNTIF(AN5:AN32,"ה.ב")) -> 0 | AO33: =(COUNTIF(AO5:AO32,"כ")+COUNTIF(AO5:AO32,"כמ"))*6+(COUNTIF(AO5:AO32,"כש")+COUNTIF(AO5:AO32,"כמש"))*10 -> 6 | AT33: יום | AW33: =COUNTIF(AX4:AX32,"י")+COUNTIF(AX4:AX32,"Y")+COUNTIF(AX4:AX32,"2") -> 6 | AY33: =COUNTIF(AZ4:AZ32,"י")+COUNTIF(AZ4:AZ32,"Y")+COUNTIF(AZ4:AZ32,"2") -> 5 | BA33: =COUNTIF(BB4:BB32,"י")+COUNTIF(BB4:BB32,"Y")+COUNTIF(BB4:BB32,"2") -> 3 | BC33: =COUNTIF(BD4:BD32,"י")+COUNTIF(BD4:BD32,"Y")+COUNTIF(BD4:BD32,"2") -> 6 | BE33: =COUNTIF(BF4:BF32,"י")+COUNTIF(BF4:BF32,"Y")+COUNTIF(BF4:BF32,"2") -> 6 | BG33: =COUNTIF(BH4:BH32,"י")+COUNTIF(BH4:BH32,"Y")+COUNTIF(BH4:BH32,"2") -> 7 | BI33: =COUNTIF(BJ4:BJ32,"י")+COUNTIF(BJ4:BJ32,"Y")+COUNTIF(BJ4:BJ32,"2") -> 5 | BK33: =COUNTIF(BL4:BL32,"י")+COUNTIF(BL4:BL32,"Y")+COUNTIF(BL4:BL32,"2") -> 5 | BM33: =COUNTIF(BN4:BN32,"י")+COUNTIF(BN4:BN32,"Y")+COUNTIF(BN4:BN32,"2") -> 5 | BO33: =COUNTIF(BP4:BP32,"י")+COUNTIF(BP4:BP32,"Y")+COUNTIF(BP4:BP32,"2") -> 4 | BQ33: =COUNTIF(BR4:BR32,"י")+COUNTIF(BR4:BR32,"Y")+COUNTIF(BR4:BR32,"2") -> 5 | BS33: =COUNTIF(BT4:BT32,"י")+COUNTIF(BT4:BT32,"Y")+COUNTIF(BT4:BT32,"2") -> 1 | BU33: =COUNTIF(BV4:BV32,"י")+COUNTIF(BV4:BV32,"Y")+COUNTIF(BV4:BV32,"2") -> 0 | BW33: =COUNTIF(BX4:BX32,"י")+COUNTIF(BX4:BX32,"Y")+COUNTIF(BX4:BX32,"2") -> 5 | BY33: =COUNTIF(BZ4:BZ32,"י")+COUNTIF(BZ4:BZ32,"Y")+COUNTIF(BZ4:BZ32,"2") -> 7 | CA33: =COUNTIF(CB4:CB32,"י")+COUNTIF(CB4:CB32,"Y")+COUNTIF(CB4:CB32,"2") -> 8 | CC33: שעות נומינלי
C34: שנתי | D34: =D33+ינואר!D36 -> 7 | E34: =E33+ינואר!E36 -> 36 | F34: =F33+ינואר!F36 -> 8 | G34: =G33+ינואר!G36 -> 40 | H34: =H33+ינואר!H36 -> 3 | I34: =I33+ינואר!I36 -> 36 | J34: =J33+ינואר!J36 -> 1 | K34: =K33+ינואר!K36 -> 18 | ... AO34: =AO33+ינואר!AO36 -> 24 | AT34: לילה | AW34: =COUNTIF(AX4:AX32,"ל")+COUNTIF(AX4:AX32,"L")+COUNTIF(AX4:AX32,"ל2") -> 7 | AY34: =COUNTIF(AZ4:AZ32,"ל")+COUNTIF(AZ4:AZ32,"L")+COUNTIF(AZ4:AZ32,"ל2") -> 7 | BA34: =COUNTIF(BB4:BB32,"ל")+COUNTIF(BB4:BB32,"L")+COUNTIF(BB4:BB32,"ל2") -> 5 | BC34: =COUNTIF(BD4:BD32,"ל")+COUNTIF(BD4:BD32,"L")+COUNTIF(BD4:BD32,"ל2") -> 4 | BE34: =COUNTIF(BF4:BF32,"ל")+COUNTIF(BF4:BF32,"L")+COUNTIF(BF4:BF32,"ל2") -> 7 | BG34: =COUNTIF(BH4:BH32,"ל")+COUNTIF(BH4:BH32,"L")+COUNTIF(BH4:BH32,"ל2") -> 7 | BI34: =COUNTIF(BJ4:BJ32,"ל")+COUNTIF(BJ4:BJ32,"L")+COUNTIF(BJ4:BJ32,"ל2") -> 7 | BK34: =COUNTIF(BL4:BL32,"ל")+COUNTIF(BL4:BL32,"L")+COUNTIF(BL4:BL32,"ל2") -> 5 | BM34: =COUNTIF(BN4:BN32,"ל")+COUNTIF(BN4:BN32,"L")+COUNTIF(BN4:BN32,"ל2") -> 11 | BO34: =COUNTIF(BP4:BP32,"ל")+COUNTIF(BP4:BP32,"L")+COUNTIF(BP4:BP32,"ל2") -> 6 | BQ34: =COUNTIF(BR4:BR32,"ל")+COUNTIF(BR4:BR32,"L")+COUNTIF(BR4:BR32,"ל2") -> 7 | BS34: =COUNTIF(BT4:BT32,"ל")+COUNTIF(BT4:BT32,"L")+COUNTIF(BT4:BT32,"ל2") -> 5 | BU34: =COUNTIF(BV4:BV32,"ל")+COUNTIF(BV4:BV32,"L")+COUNTIF(BV4:BV32,"ל2") -> 0 | BW34: =COUNTIF(BX4:BX32,"ל")+COUNTIF(BX4:BX32,"L")+COUNTIF(BX4:BX32,"ל2") -> 8 | BY34: =COUNTIF(BZ4:BZ32,"ל")+COUNTIF(BZ4:BZ32,"L")+COUNTIF(BZ4:BZ32,"ל2") -> 5 | CA34: =COUNTIF(CB4:CB32,"ל")+COUNTIF(CB4:CB32,"L")+COUNTIF(CB4:CB32,"ל2") -> 6
AW35: =(AW33*12)+(AW34*12)+(COUNTIF(AX4:AX32,"ק")*8)+(COUNTIF(AX4:AX32,"ח")*8)+(COUNTIF(AX4:AX32,"מ")*8)+(COUNTIF(AX4:AX32,"מיל")*8) -> 164 | AY35: =(AY33*12)+(AY34*12)+(COUNTIF(AZ4:AZ32,"ק")*8)+(COUNTIF(AZ4:AZ32,"ח")*8)+(COUNTIF(AZ4:AZ32,"מ")*8)+(COUNTIF(AZ4:AZ32,"מיל")*8) -> 160 | BA35: =(BA33*12)+(BA34*12)+(COUNTIF(BB4:BB32,"ק")*8)+(COUNTIF(BB4:BB32,"ח")*8)+(COUNTIF(BB4:BB32,"מ")*8)+(COUNTIF(BB4:BB32,"מיל")*8) -> 160 | BC35: =(BC33*12)+(BC34*12)+(COUNTIF(BD4:BD32,"ק")*8)+(COUNTIF(BD4:BD32,"ח")*8)+(COUNTIF(BD4:BD32,"מ")*8)+(COUNTIF(BD4:BD32,"מיל")*8) -> 184 | BE35: =(BE33*12)+(BE34*12)+(COUNTIF(BF4:BF32,"ק")*8)+(COUNTIF(BF4:BF32,"ח")*8)+(COUNTIF(BF4:BF32,"מ")*8)+(COUNTIF(BF4:BF32,"מיל")*8) -> 172 | BG35: =(BG33*12)+(BG34*12)+(COUNTIF(BH4:BH32,"ק")*8)+(COUNTIF(BH4:BH32,"ח")*8)+(COUNTIF(BH4:BH32,"מ")*8)+(COUNTIF(BH4:BH32,"מיל")*8) -> 168 | BI35: =(BI33*12)+(BI34*12)+(COUNTIF(BJ4:BJ32,"ק")*8)+(COUNTIF(BJ4:BJ32,"ח")*8)+(COUNTIF(BJ4:BJ32,"מ")*8)+(COUNTIF(BJ4:BJ32,"מיל")*8) -> 152 | BK35: =(BK33*12)+(BK34*12)+(COUNTIF(BL4:BL32,"ק")*8)+(COUNTIF(BL4:BL32,"ח")*8)+(COUNTIF(BL4:BL32,"מ")*8)+(COUNTIF(BL4:BL32,"מיל")*8) -> 144 | BM35: =(BM33*12)+(BM34*12)+(COUNTIF(BN4:BN32,"ק")*8)+(COUNTIF(BN4:BN32,"ח")*8)+(COUNTIF(BN4:BN32,"מ")*8)+(COUNTIF(BN4:BN32,"מיל")*8) -> 192 | BO35: =(BO33*12)+(BO34*12)+(COUNTIF(BP4:BP32,"ק")*8)+(COUNTIF(BP4:BP32,"ח")*8)+(COUNTIF(BP4:BP32,"מ")*8)+(COUNTIF(BP4:BP32,"מיל")*8) -> 152 | BQ35: =(BQ33*12)+(BQ34*12)+(COUNTIF(BR4:BR32,"ק")*8)+(COUNTIF(BR4:BR32,"ח")*8)+(COUNTIF(BR4:BR32,"מ")*8)+(COUNTIF(BR4:BR32,"מיל")*8) -> 160 | BS35: =(BS33*12)+(BS34*12)+(COUNTIF(BT4:BT32,"ק")*8)+(COUNTIF(BT4:BT32,"ח")*8)+(COUNTIF(BT4:BT32,"מ")*8)+(COUNTIF(BT4:BT32,"מיל")*8) -> 160 | BU35: =(BU33*12)+(BU34*12)+(COUNTIF(BV4:BV32,"ק")*8)+(COUNTIF(BV4:BV32,"ח")*8)+(COUNTIF(BV4:BV32,"מ")*8)+(COUNTIF(BV4:BV32,"מיל")*8) -> 0 | BW35: =(BW33*12)+(BW34*12)+(COUNTIF(BX4:BX32,"ק")*8)+(COUNTIF(BX4:BX32,"ח")*8)+(COUNTIF(BX4:BX32,"מ")*8)+(COUNTIF(BX4:BX32,"מיל")*8) -> 164 | BY35: =(BY33*12)+(BY34*12)+(COUNTIF(BZ4:BZ32,"ק")*8)+(COUNTIF(BZ4:BZ32,"ח")*8)+(COUNTIF(BZ4:BZ32,"מ")*8)+(COUNTIF(BZ4:BZ32,"מיל")*8) -> 152 | CA35: =(CA33*12)+(CA34*12)+(COUNTIF(CB4:CB32,"ק")*8)+(COUNTIF(CB4:CB32,"ח")*8)+(COUNTIF(CB4:CB32,"מ")*8)+(COUNTIF(CB4:CB32,"מיל")*8) -> 168 | CC35: 160
AW36: =AW35-CC35 -> 4 | AY36: =AY35-CC35 -> 0 | BA36: =BA35-CC35 -> 0 | BC36: =BC35-CC35 -> 24 | BE36: =BE35-CC35 -> 12 | BG36: =BG35-CC35 -> 8 | BI36: =BI35-CC35 -> -8 | BK36: =BK35-CC35 -> -16 | BM36: =BM35-CC35 -> 32 | BO36: =BO35-CC35 -> -8 | BQ36: =BQ35-CC35 -> 0 | BS36: =BS35-CC35 -> 0 | BU36: =BU35-CC35 -> -160 | BW36: =BW35-CC35 -> 4 | BY36: =BY35-CC35 -> -8 | CA36: =CA35-CC35 -> 8 | CC36: חוסר לנומינלי

Sheet מרץ
A1: מרץ אדר-ניסן | AT1: 3 | AW1: עובדי משמרת | CC1: 3
X2: רמ"ד פיקוד | Z2: רמ"ח | AB2: ה.חשמל\מ. מחסן | AF2: רמ"ד ת.מסלול | AH2: מדור תאורת מסלולים | AP2: הערות | AR2: רכבים | AW2: משמרת 1 | BE2: משמרת 2 | BM2: משמרת 3 | BU2: משמרת 4 | CF2: כמות עובדים | CH2: עבודות מסלולים | CJ2: הערות
D3: קובי דניאלי | F3: תומר סער | H3: עמית נדל | J3: דניאל סויסה | L3: מיכאל דניאל | N3: יואב ברדוגו | P3: דוד מהלו | R3: אלון איברנדי | T3: סהר קובה | V3: שגיב בניתה | X3: אבי מנור | Z3: מוטי חלפון | AB3: איציק אפרמשוילי | AD3: אבי שמואלי | AF3: שמוליק פוגל | AH3: אלי פבלוב | AJ3: ראובן בוזנח | AL3: גיטאו אבבה | AN3: תומר ליבוביץ | AW3: שתה בירו | AY3: ליאור אברהם | BA3: ברק מור | BC3: אדם כהן | BE3: מרבי קריכלי | BG3: ירון טייב | BI3: עומרי סלמן | BK3: גבריאל וכטרמן | BM3: שלומי חן | BO3: אור שלו | BQ3: עומר גבע | BS3: איציק חוחא | BW3: שי סואד | BY3: דור שרוני | CA3: אורגד שניאור
